Workbook

Sheet README
A1: India CPI Inflation Case Study - Excel workbook
A3: Sheets
A4: Data: raw CSV (month labels fixed, NA left blank).
A5: RU_Raw -> RU_Clean: Rural+Urban rows laid out Jan-2013..May-2023; missing values imputed in RU_Clean.
A6: MoM / YoY: month-on-month and year-on-year % change for every category.
A7: Q1..Q5: one sheet per question. Green cells = answers. Every number is a formula.
A9: Colour code
A10: Blue text on yellow = input you can change. Green text = pulled from another sheet. Black = calculation.
A12: Data cleaning log
A13: 1) Month typo "Marcrh" (Rural+Urban, 2014) corrected to March; "November " trailing space removed.
A14: 2) April 2019 is absent from the file for all sectors -> added as a blank row and imputed (average of Mar and May).
A15: 3) April and May 2020 have NA values (lockdown) -> imputed with straight-line interpolation.
... A22: Q5 needs monthly Indian Basket crude prices (PPAC, ppac.gov.in). Six verified monthly points are pre-filled; fill the rest to see correlations.

Sheet Data
A1: Sector | B1: Year | C1: Month | D1: Cereals and products | E1: Meat and fish | F1: Egg | G1: Milk and products | H1: Oils and fats | I1: Fruits | J1: Vegetables | K1: Pulses and products | L1: Sugar and Confectionery | M1: Spices | N1: Non-alcoholic beverages | O1: Prepared meals, snacks, sweets etc. | P1: Food and beverages | Q1: Pan, tobacco and intoxicants | R1: Clothing | S1: Footwear | T1: Clothing and footwear | U1: Housing | V1: Fuel and light | W1: Household goods and services | X1: Health | Y1: Transport and communication | Z1: Recreation and amusement | AA1: Education | AB1: Personal care and effects | AC1: Miscellaneous | AD1: General index | AE1: Key
A2: Rural | B2: 2013 | C2: January | D2: 107.5 | E2: 106.3 | F2: 108.1 | G2: 104.9 | H2: 106.1 | I2: 103.9 | J2: 101.9 | K2: 106.1 | L2: 106.8 | M2: 103.1 | N2: 104.8 | O2: 106.7 | P2: 105.5 | Q2: 105.1 | R2: 106.5 | S2: 105.8 | T2: 106.4 | V2: 105.5 | W2: 104.8 | X2: 104 | Y2: 103.3 | Z2: 103.4 | AA2: 103.8 | AB2: 104.7 | AC2: 104 | AD2: 105.1 | AE2: =A2&"|"&B2&"|"&C2 -> Rural|2013|January
A3: Urban | B3: 2013 | C3: January | D3: 110.5 | E3: 109.1 | F3: 113 | G3: 103.6 | H3: 103.4 | I3: 102.3 | J3: 102.9 | K3: 105.8 | L3: 105.1 | M3: 101.8 | N3: 105.1 | O3: 107.9 | P3: 105.9 | Q3: 105.2 | R3: 105.9 | S3: 105 | T3: 105.8 | U3: 100.3 | V3: 105.4 | W3: 104.8 | X3: 104.1 | Y3: 103.2 | Z3: 102.9 | AA3: 103.5 | AB3: 104.3 | AC3: 103.7 | AD3: 104 | AE3: =A3&"|"&B3&"|"&C3 -> Urban|2013|January
A4: Rural+Urban | B4: 2013 | C4: January | D4: 108.4 | E4: 107.3 | F4: 110 | G4: 104.4 | H4: 105.1 | I4: 103.2 | J4: 102.2 | K4: 106 | L4: 106.2 | M4: 102.7 | N4: 104.9 | O4: 107.3 | P4: 105.6 | Q4: 105.1 | R4: 106.3 | S4: 105.5 | T4: 106.2 | U4: 100.3 | V4: 105.5 | W4: 104.8 | X4: 104 | Y4: 103.2 | Z4: 103.1 | AA4: 103.6 | AB4: 104.5 | AC4: 103.9 | AD4: 104.6 | AE4: =A4&"|"&B4&"|"&C4 -> Rural+Urban|2013|January
A5: Rural | B5: 2013 | C5: February | D5: 109.2 | E5: 108.7 | F5: 110.2 | G5: 105.4 | H5: 106.7 | I5: 104 | J5: 102.4 | K5: 105.9 | L5: 105.7 | M5: 103.1 | N5: 105.1 | O5: 107.7 | P5: 106.3 | Q5: 105.6 | R5: 107.1 | S5: 106.3 | T5: 107 | V5: 106.2 | W5: 105.2 | X5: 104.4 | Y5: 103.9 | Z5: 104 | AA5: 104.1 | AB5: 104.6 | AC5: 104.4 | AD5: 105.8 | AE5: =A5&"|"&B5&"|"&C5 -> Rural|2013|February
A6: Urban | B6: 2013 | C6: February | D6: 112.9 | E6: 112.9 | F6: 116.9 | G6: 104 | H6: 103.5 | I6: 103.1 | J6: 104.9 | K6: 104.1 | L6: 103.8 | M6: 102.3 | N6: 106 | O6: 109 | P6: 107.2 | Q6: 106 | R6: 106.6 | S6: 105.5 | T6: 106.4 | U6: 100.4 | V6: 105.7 | W6: 105.2 | X6: 104.7 | Y6: 104.4 | Z6: 103.3 | AA6: 103.7 | AB6: 104.3 | AC6: 104.3 | AD6: 104.7 | AE6: =A6&"|"&B6&"|"&C6 -> Urban|2013|February
A7: Rural+Urban | B7: 2013 | C7: February | D7: 110.4 | E7: 110.2 | F7: 112.8 | G7: 104.9 | H7: 105.5 | I7: 103.6 | J7: 103.2 | K7: 105.3 | L7: 105.1 | M7: 102.8 | N7: 105.5 | O7: 108.3 | P7: 106.6 | Q7: 105.7 | R7: 106.9 | S7: 106 | T7: 106.8 | U7: 100.4 | V7: 106 | W7: 105.2 | X7: 104.5 | Y7: 104.2 | Z7: 103.6 | AA7: 103.9 | AB7: 104.5 | AC7: 104.4 | AD7: 105.3 | AE7: =A7&"|"&B7&"|"&C7 -> Rural+Urban|2013|February
A8: Rural | B8: 2013 | C8: March | D8: 110.2 | E8: 108.8 | F8: 109.9 | G8: 105.6 | H8: 106.2 | I8: 105.7 | J8: 101.4 | K8: 105.7 | L8: 105 | M8: 103.3 | N8: 105.6 | O8: 108.2 | P8: 106.6 | Q8: 106.5 | R8: 107.6 | S8: 106.8 | T8: 107.5 | V8: 106.1 | W8: 105.6 | X8: 104.7 | Y8: 104.6 | Z8: 104 | AA8: 104.3 | AB8: 104.3 | AC8: 104.6 | AD8: 106 | AE8: =A8&"|"&B8&"|"&C8 -> Rural|2013|March
A9: Urban | B9: 2013 | C9: March | D9: 113.9 | E9: 111.4 | F9: 113.2 | G9: 104.3 | H9: 102.7 | I9: 104.9 | J9: 103.8 | K9: 103.5 | L9: 102.6 | M9: 102.4 | N9: 107 | O9: 109.8 | P9: 107.3 | Q9: 106.8 | R9: 107.2 | S9: 106 | T9: 107 | U9: 100.4 | V9: 106 | W9: 105.7 | X9: 105.2 | Y9: 105.5 | Z9: 103.5 | AA9: 103.8 | AB9: 104.2 | AC9: 104.9 | AD9: 105 | AE9: =A9&"|"&B9&"|"&C9 -> Urban|2013|March
A10: Rural+Urban | B10: 2013 | C10: March | D10: 111.4 | E10: 109.7 | F10: 111.2 | G10: 105.1 | H10: 104.9 | I10: 105.3 | J10: 102.2 | K10: 105 | L10: 104.2 | M10: 103 | N10: 106.2 | O10: 108.9 | P10: 106.9 | Q10: 106.6 | R10: 107.4 | S10: 106.5 | T10: 107.3 | U10: 100.4 | V10: 106.1 | W10: 105.6 | X10: 104.9 | Y10: 105.1 | Z10: 103.7 | AA10: 104 | AB10: 104.3 | AC10: 104.7 | AD10: 105.5 | AE10: =A10&"|"&B10&"|"&C10 -> Rural+Urban|2013|March
A11: Rural | B11: 2013 | C11: April | D11: 110.2 | E11: 109.5 | F11: 106.9 | G11: 106.3 | H11: 105.7 | I11: 108.3 | J11: 103.4 | K11: 105.7 | L11: 104.2 | M11: 103.2 | N11: 106.5 | O11: 108.8 | P11: 107.1 | Q11: 107.1 | R11: 108.1 | S11: 107.4 | T11: 108 | V11: 106.5 | W11: 106.1 | X11: 105.1 | Y11: 104.4 | Z11: 104.5 | AA11: 104.8 | AB11: 102.7 | AC11: 104.6 | AD11: 106.4 | AE11: =A11&"|"&B11&"|"&C11 -> Rural|2013|April
A12: Urban | B12: 2013 | C12: April | D12: 114.6 | E12: 113.4 | F12: 106 | G12: 104.7 | H12: 102.1 | I12: 109.5 | J12: 109.7 | K12: 104.6 | L12: 102 | M12: 103.5 | N12: 108.2 | O12: 110.6 | P12: 108.8 | Q12: 108.5 | R12: 107.9 | S12: 106.4 | T12: 107.7 | U12: 100.5 | V12: 106.4 | W12: 106.5 | X12: 105.7 | Y12: 105 | Z12: 104 | AA12: 105.2 | AB12: 103.2 | AC12: 105.1 | AD12: 105.7 | AE12: =A12&"|"&B12&"|"&C12 -> Urban|2013|April
A13: Rural+Urban | B13: 2013 | C13: April | D13: 111.6 | E13: 110.9 | F13: 106.6 | G13: 105.7 | H13: 104.4 | I13: 108.9 | J13: 105.5 | K13: 105.3 | L13: 103.5 | M13: 103.3 | N13: 107.2 | O13: 109.6 | P13: 107.7 | Q13: 107.5 | R13: 108 | S13: 107 | T13: 107.9 | U13: 100.5 | V13: 106.5 | W13: 106.3 | X13: 105.3 | Y13: 104.7 | Z13: 104.2 | AA13: 105 | AB13: 102.9 | AC13: 104.8 | AD13: 106.1 | AE13: =A13&"|"&B13&"|"&C13 -> Rural+Urban|2013|April
A14: Rural | B14: 2013 | C14: May | D14: 110.9 | E14: 109.8 | F14: 105.9 | G14: 107.5 | H14: 105.3 | I14: 108.1 | J14: 107.3 | K14: 106.1 | L14: 103.7 | M14: 104 | N14: 107.4 | O14: 109.9 | P14: 108.1 | Q14: 108.1 | R14: 108.8 | S14: 107.9 | T14: 108.6 | V14: 107.5 | W14: 106.8 | X14: 105.7 | Y14: 104.1 | Z14: 105 | AA14: 105.5 | AB14: 102.1 | AC14: 104.8 | AD14: 107.2 | AE14: =A14&"|"&B14&"|"&C14 -> Rural|2013|May
A15: Urban | B15: 2013 | C15: May | D15: 115.4 | E15: 114.2 | F15: 102.7 | G15: 105.5 | H15: 101.5 | I15: 110.6 | J15: 123.7 | K15: 105.2 | L15: 101.9 | M15: 105 | N15: 109.1 | O15: 111.3 | P15: 111.1 | Q15: 109.8 | R15: 108.5 | S15: 106.7 | T15: 108.3 | U15: 100.5 | V15: 107.2 | W15: 107.1 | X15: 106.2 | Y15: 103.9 | Z15: 104.6 | AA15: 105.7 | AB15: 102.6 | AC15: 104.9 | AD15: 106.6 | AE15: =A15&"|"&B15&"|"&C15 -> Urban|2013|May
A16: Rural+Urban | B16: 2013 | C16: May | D16: 112.3 | E16: 111.3 | F16: 104.7 | G16: 106.8 | H16: 103.9 | I16: 109.3 | J16: 112.9 | K16: 105.8 | L16: 103.1 | M16: 104.3 | N16: 108.1 | O16: 110.5 | P16: 109.2 | Q16: 108.6 | R16: 108.7 | S16: 107.4 | T16: 108.5 | U16: 100.5 | V16: 107.4 | W16: 106.9 | X16: 105.9 | Y16: 104 | Z16: 104.8 | AA16: 105.6 | AB16: 102.3 | AC16: 104.8 | AD16: 106.9 | AE16: =A16&"|"&B16&"|"&C16 -> Rural+Urban|2013|May
A17: Rural | B17: 2013 | C17: June | D17: 112.3 | E17: 112.1 | F17: 108.1 | G17: 108.3 | H17: 105.9 | I17: 109.2 | J17: 118 | K17: 106.8 | L17: 104.1 | M17: 105.4 | N17: 108.2 | O17: 111 | P17: 110.6 | Q17: 109 | R17: 109.7 | S17: 108.8 | T17: 109.5 | V17: 108.5 | W17: 107.5 | X17: 106.3 | Y17: 105 | Z17: 105.6 | AA17: 106.5 | AB17: 102.5 | AC17: 105.5 | AD17: 108.9 | AE17: =A17&"|"&B17&"|"&C17 -> Rural|2013|June
A18: Urban | B18: 2013 | C18: June | D18: 117 | E18: 120.1 | F18: 112.5 | G18: 107.3 | H18: 101.3 | I18: 112.4 | J18: 143.6 | K18: 105.4 | L18: 101.4 | M18: 106.4 | N18: 110 | O18: 112.2 | P18: 115 | Q18: 110.9 | R18: 109.2 | S18: 107.2 | T18: 108.9 | U18: 106.6 | V18: 108 | W18: 107.7 | X18: 106.5 | Y18: 105.2 | Z18: 105.2 | AA18: 108.1 | AB18: 103.3 | AC18: 106.1 | AD18: 109.7 | AE18: =A18&"|"&B18&"|"&C18 -> Urban|2013|June
A19: Rural+Urban | B19: 2013 | C19: June | D19: 113.8 | E19: 114.9 | F19: 109.8 | G19: 107.9 | H19: 104.2 | I19: 110.7 | J19: 126.7 | K19: 106.3 | L19: 103.2 | M19: 105.7 | N19: 109 | O19: 111.6 | P19: 112.2 | Q19: 109.5 | R19: 109.5 | S19: 108.1 | T19: 109.3 | U19: 106.6 | V19: 108.3 | W19: 107.6 | X19: 106.4 | Y19: 105.1 | Z19: 105.4 | AA19: 107.4 | AB19: 102.8 | AC19: 105.8 | AD19: 109.3 | AE19: =A19&"|"&B19&"|"&C19 -> Rural+Urban|2013|June
A20: Rural | B20: 2013 | C20: July | D20: 113.4 | E20: 114.9 | F20: 110.5 | G20: 109.3 | H20: 106.2 | I20: 110.3 | J20: 129.2 | K20: 107.1 | L20: 104.3 | M20: 106.4 | N20: 109.1 | O20: 112.1 | P20: 113.1 | Q20: 109.8 | R20: 110.5 | S20: 109.5 | T20: 110.3 | V20: 109.5 | W20: 108.3 | X20: 106.9 | Y20: 106.8 | Z20: 106.4 | AA20: 107.8 | AB20: 102.5 | AC20: 106.5 | AD20: 110.7 | AE20: =A20&"|"&B20&"|"&C20 -> Rural|2013|July
A21: Urban | B21: 2013 | C21: July | D21: 117.8 | E21: 119.2 | F21: 114 | G21: 108.3 | H21: 101.1 | I21: 113.2 | J21: 160.9 | K21: 105.1 | L21: 101.3 | M21: 107.5 | N21: 110.4 | O21: 113.1 | P21: 117.5 | Q21: 111.7 | R21: 109.8 | S21: 107.8 | T21: 109.5 | U21: 107.7 | V21: 108.6 | W21: 108.1 | X21: 107.1 | Y21: 107.3 | Z21: 105.9 | AA21: 110.1 | AB21: 103.2 | AC21: 107.3 | AD21: 111.4 | AE21: =A21&"|"&B21&"|"&C21 -> Urban|2013|July
A22: Rural+Urban | B22: 2013 | C22: July | D22: 114.8 | E22: 116.4 | F22: 111.9 | G22: 108.9 | H22: 104.3 | I22: 111.7 | J22: 140 | K22: 106.4 | L22: 103.3 | M22: 106.8 | N22: 109.6 | O22: 112.6 | P22: 114.7 | Q22: 110.3 | R22: 110.2 | S22: 108.8 | T22: 110 | U22: 107.7 | V22: 109.2 | W22: 108.2 | X22: 107 | Y22: 107.1 | Z22: 106.1 | AA22: 109.1 | AB22: 102.8 | AC22: 106.9 | AD22: 111 | AE22: =A22&"|"&B22&"|"&C22 -> Rural+Urban|2013|July
A23: Rural | B23: 2013 | C23: August | D23: 114.3 | E23: 115.4 | F23: 111.1 | G23: 110 | H23: 106.4 | I23: 110.8 | J23: 138.9 | K23: 107.4 | L23: 104.1 | M23: 106.9 | N23: 109.7 | O23: 112.6 | P23: 114.9 | Q23: 110.7 | R23: 111.3 | S23: 110.2 | T23: 111.1 | V23: 109.9 | W23: 108.7 | X23: 107.5 | Y23: 107.8 | Z23: 106.8 | AA23: 108.7 | AB23: 105 | AC23: 107.5 | AD23: 112.1 | AE23: =A23&"|"&B23&"|"&C23 -> Rural|2013|August
A24: Urban | B24: 2013 | C24: August | D24: 118.3 | E24: 120.4 | F24: 112.7 | G24: 108.9 | H24: 101.1 | I24: 108.7 | J24: 177 | K24: 104.7 | L24: 101 | M24: 108.5 | N24: 110.9 | O24: 114.3 | P24: 119.6 | Q24: 112.4 | R24: 110.6 | S24: 108.3 | T24: 110.2 | U24: 108.9 | V24: 109.3 | W24: 108.7 | X24: 107.6 | Y24: 108.1 | Z24: 106.5 | AA24: 110.8 | AB24: 106 | AC24: 108.3 | AD24: 112.7 | AE24: =A24&"|"&B24&"|"&C24 -> Urban|2013|August
A25: Rural+Urban | B25: 2013 | C25: August | D25: 115.6 | E25: 117.2 | F25: 111.7 | G25: 109.6 | H25: 104.5 | I25: 109.8 | J25: 151.8 | K25: 106.5 | L25: 103.1 | M25: 107.4 | N25: 110.2 | O25: 113.4 | P25: 116.6 | Q25: 111.2 | R25: 111 | S25: 109.4 | T25: 110.7 | U25: 108.9 | V25: 109.7 | W25: 108.7 | X25: 107.5 | Y25: 108 | Z25: 106.6 | AA25: 109.9 | AB25: 105.4 | AC25: 107.9 | AD25: 112.4 | AE25: =A25&"|"&B25&"|"&C25 -> Rural+Urban|2013|August
A26: Rural | B26: 2013 | C26: September | D26: 115.4 | E26: 115.7 | F26: 111.7 | G26: 111 | H26: 107.4 | I26: 110.9 | J26: 154 | K26: 108.1 | L26: 104.2 | M26: 107.9 | N26: 110.4 | O26: 114 | P26: 117.8 | Q26: 111.7 | R26: 112.7 | S26: 111.4 | T26: 112.5 | V26: 111.1 | W26: 109.6 | X26: 108.3 | Y26: 109.3 | Z26: 107.7 | AA26: 109.8 | AB26: 106.7 | AC26: 108.7 | AD26: 114.2 | AE26: =A26&"|"&B26&"|"&C26 -> Rural|2013|September
A27: Urban | B27: 2013 | C27: September | D27: 118.6 | E27: 119.1 | F27: 113.2 | G27: 109.6 | H27: 101.7 | I27: 103.2 | J27: 174.3 | K27: 105.1 | L27: 100.8 | M27: 109.1 | N27: 111.1 | O27: 115.4 | P27: 119.2 | Q27: 112.9 | R27: 111.4 | S27: 109 | T27: 111.1 | U27: 109.7 | V27: 109.5 | W27: 109.6 | X27: 107.9 | Y27: 110.4 | Z27: 107.4 | AA27: 111.2 | AB27: 106.9 | AC27: 109.4 | AD27: 113.2 | AE27: =A27&"|"&B27&"|"&C27 -> Urban|2013|September
A28: Rural+Urban | B28: 2013 | C28: September | D28: 116.4 | E28: 116.9 | F28: 112.3 | G28: 110.5 | H28: 105.3 | I28: 107.3 | J28: 160.9 | K28: 107.1 | L28: 103.1 | M28: 108.3 | N28: 110.7 | O28: 114.6 | P28: 118.3 | Q28: 112 | R28: 112.2 | S28: 110.4 | T28: 111.9 | U28: 109.7 | V28: 110.5 | W28: 109.6 | X28: 108.1 | Y28: 109.9 | Z28: 107.5 | AA28: 110.6 | AB28: 106.8 | AC28: 109 | AD28: 113.7 | AE28: =A28&"|"&B28&"|"&C28 -> Rural+Urban|2013|September
A29: Rural | B29: 2013 | C29: October | D29: 116.3 | E29: 115.4 | F29: 112.6 | G29: 111.7 | H29: 107.7 | I29: 113.2 | J29: 164.9 | K29: 108.3 | L29: 103.9 | M29: 108.2 | N29: 111.1 | O29: 114.9 | P29: 119.8 | Q29: 112.2 | R29: 113.6 | S29: 112.3 | T29: 113.4 | V29: 111.6 | W29: 110.4 | X29: 108.9 | Y29: 109.3 | Z29: 108.3 | AA29: 110.2 | AB29: 107.5 | AC29: 109.1 | AD29: 115.5 | AE29: =A29&"|"&B29&"|"&C29 -> Rural|2013|October
A30: Urban | B30: 2013 | C30: October | D30: 118.9 | E30: 118.1 | F30: 114.5 | G30: 110.4 | H30: 102.3 | I30: 106.2 | J30: 183.5 | K30: 105.3 | L30: 100.2 | M30: 109.6 | N30: 111.4 | O30: 116 | P30: 120.8 | Q30: 113.5 | R30: 112.5 | S30: 109.7 | T30: 112 | U30: 110.5 | V30: 109.7 | W30: 110.2 | X30: 108.2 | Y30: 109.7 | Z30: 108 | AA30: 111.3 | AB30: 107.3 | AC30: 109.4 | AD30: 114 | AE30: =A30&"|"&B30&"|"&C30 -> Urban|2013|October
A31: Rural+Urban | B31: 2013 | C31: October | D31: 117.1 | E31: 116.3 | F31: 113.3 | G31: 111.2 | H31: 105.7 | I31: 109.9 | J31: 171.2 | K31: 107.3 | L31: 102.7 | M31: 108.7 | N31: 111.2 | O31: 115.4 | P31: 120.2 | Q31: 112.5 | R31: 113.2 | S31: 111.2 | T31: 112.8 | U31: 110.5 | V31: 110.9 | W31: 110.3 | X31: 108.6 | Y31: 109.5 | Z31: 108.1 | AA31: 110.8 | AB31: 107.4 | AC31: 109.2 | AD31: 114.8 | AE31: =A31&"|"&B31&"|"&C31 -> Rural+Urban|2013|October
A32: Rural | B32: 2013 | C32: November | D32: 117.3 | E32: 114.9 | F32: 116.2 | G32: 112.8 | H32: 108.9 | I32: 116.6 | J32: 178.1 | K32: 109.1 | L32: 103.6 | M32: 109 | N32: 111.8 | O32: 116 | P32: 122.5 | Q32: 112.8 | R32: 114.6 | S32: 113.1 | T32: 114.4 | V32: 112.6 | W32: 111.3 | X32: 109.7 | Y32: 109.6 | Z32: 108.7 | AA32: 111 | AB32: 108.2 | AC32: 109.8 | AD32: 117.4 | AE32: =A32&"|"&B32&"|"&C32 -> Rural|2013|November
A33: Urban | B33: 2013 | C33: November | D33: 119.8 | E33: 116.3 | F33: 122.6 | G33: 112 | H33: 103.2 | I33: 110 | J33: 192.8 | K33: 106.3 | L33: 99.5 | M33: 110.3 | N33: 111.8 | O33: 117.1 | P33: 122.9 | Q33: 114.1 | R33: 113.5 | S33: 110.3 | T33: 113 | U33: 111.1 | V33: 110 | W33: 110.9 | X33: 108.6 | Y33: 109.5 | Z33: 108.5 | AA33: 111.3 | AB33: 107.9 | AC33: 109.6 | AD33: 115 | AE33: =A33&"|"&B33&"|"&C33 -> Urban|2013|November
A34: Rural+Urban | B34: 2013 | C34: November | D34: 118.1 | E34: 115.4 | F34: 118.7 | G34: 112.5 | H34: 106.8 | I34: 113.5 | J34: 183.1 | K34: 108.2 | L34: 102.2 | M34: 109.4 | N34: 111.8 | O34: 116.5 | P34: 122.6 | Q34: 113.1 | R34: 114.2 | S34: 111.9 | T34: 113.8 | U34: 111.1 | V34: 111.6 | W34: 111.1 | X34: 109.3 | Y34: 109.5 | Z34: 108.6 | AA34: 111.2 | AB34: 108.1 | AC34: 109.7 | AD34: 116.3 | AE34: =A34&"|"&B34&"|"&C34 -> Rural+Urban|2013|November
A35: Rural | B35: 2013 | C35: December | D35: 118.4 | E35: 115.9 | F35: 120.4 | G35: 113.8 | H35: 109.5 | I35: 115.5 | J35: 145.7 | K35: 109.5 | L35: 102.9 | M35: 109.8 | N35: 112.1 | O35: 116.8 | P35: 118.7 | Q35: 113.6 | R35: 115.8 | S35: 114 | T35: 115.5 | V35: 112.8 | W35: 112.1 | X35: 110.1 | Y35: 109.9 | Z35: 109.2 | AA35: 111.6 | AB35: 108.1 | AC35: 110.1 | AD35: 115.5 | AE35: =A35&"|"&B35&"|"&C35 -> Rural|2013|December
A36: Urban | B36: 2013 | C36: December | D36: 120.5 | E36: 118.1 | F36: 128.5 | G36: 112.8 | H36: 103.4 | I36: 110.7 | J36: 144.8 | K36: 107.1 | L36: 98.6 | M36: 111.9 | N36: 112.1 | O36: 118.1 | P36: 117.8 | Q36: 115 | R36: 114.2 | S36: 110.9 | T36: 113.7 | U36: 110.7 | V36: 110.4 | W36: 111.3 | X36: 109 | Y36: 109.7 | Z36: 108.9 | AA36: 111.4 | AB36: 107.7 | AC36: 109.8 | AD36: 113.3 | AE36: =A36&"|"&B36&"|"&C36 -> Urban|2013|December
A37: Rural+Urban | B37: 2013 | C37: December | D37: 119.1 | E37: 116.7 | F37: 123.5 | G37: 113.4 | H37: 107.3 | I37: 113.3 | J37: 145.4 | K37: 108.7 | L37: 101.5 | M37: 110.5 | N37: 112.1 | O37: 117.4 | P37: 118.4 | Q37: 114 | R37: 115.2 | S37: 112.7 | T37: 114.8 | U37: 110.7 | V37: 111.9 | W37: 111.7 | X37: 109.7 | Y37: 109.8 | Z37: 109 | AA37: 111.5 | AB37: 107.9 | AC37: 110 | AD37: 114.5 | AE37: =A37&"|"&B37&"|"&C37 -> Rural+Urban|2013|December
A38: Rural | B38: 2014 | C38: January | D38: 118.9 | E38: 117.1 | F38: 120.5 | G38: 114.4 | H38: 109 | I38: 115.5 | J38: 123.9 | K38: 109.6 | L38: 101.8 | M38: 110.2 | N38: 112.4 | O38: 117.3 | P38: 116 | Q38: 114 | R38: 116.5 | S38: 114.5 | T38: 116.2 | V38: 113 | W38: 112.6 | X38: 110.6 | Y38: 110.5 | Z38: 109.6 | AA38: 111.8 | AB38: 108.3 | AC38: 110.6 | AD38: 114.2 | AE38: =A38&"|"&B38&"|"&C38 -> Rural|2014|January
A39: Urban | B39: 2014 | C39: January | D39: 121.2 | E39: 122 | F39: 129.9 | G39: 113.6 | H39: 102.9 | I39: 112.1 | J39: 118.9 | K39: 107.5 | L39: 96.9 | M39: 112.7 | N39: 112.1 | O39: 119 | P39: 115.5 | Q39: 115.7 | R39: 114.8 | S39: 111.3 | T39: 114.3 | U39: 111.6 | V39: 111 | W39: 111.9 | X39: 109.7 | Y39: 110.8 | Z39: 109.8 | AA39: 111.5 | AB39: 108 | AC39: 110.5 | AD39: 112.9 | AE39: =A39&"|"&B39&"|"&C39 -> Urban|2014|January
A40: Rural+Urban | B40: 2014 | C40: January | D40: 119.6 | E40: 118.8 | F40: 124.1 | G40: 114.1 | H40: 106.8 | I40: 113.9 | J40: 122.2 | K40: 108.9 | L40: 100.2 | M40: 111 | N40: 112.3 | O40: 118.1 | P40: 115.8 | Q40: 114.5 | R40: 115.8 | S40: 113.2 | T40: 115.4 | U40: 111.6 | V40: 112.2 | W40: 112.3 | X40: 110.3 | Y40: 110.7 | Z40: 109.7 | AA40: 111.6 | AB40: 108.2 | AC40: 110.6 | AD40: 113.6 | AE40: =A40&"|"&B40&"|"&C40 -> Rural+Urban|2014|January
...

Sheet RU_Raw
A1: Rural+Urban index - raw (lookup from Data, NA stays blank)
A2: Row = every month Jan-2013..May-2023. Blank = value missing in source file.
A4: Year | B4: MonthNo | C4: Month | D4: Date | E4: Key | F4: Data row | G4: Cereals and products | H4: Meat and fish | I4: Egg | J4: Milk and products | K4: Oils and fats | L4: Fruits | M4: Vegetables | N4: Pulses and products | O4: Sugar and Confectionery | P4: Spices | Q4: Non-alcoholic beverages | R4: Prepared meals, snacks, sweets etc. | S4: Food and beverages | T4: Pan, tobacco and intoxicants | U4: Clothing | V4: Footwear | W4: Clothing and footwear | X4: Housing | Y4: Fuel and light | Z4: Household goods and services | AA4: Health | AB4: Transport and communication | AC4: Recreation and amusement | AD4: Education | AE4: Personal care and effects | AF4: Miscellaneous | AG4: General index
A5: 2013 | B5: 1 | C5: January | D5: =DATE(A5,B5,1) -> 41275 | E5: ="Rural+Urban|"&A5&"|"&C5 -> Rural+Urban|2013|January | F5: =IFERROR(MATCH(E5,Data!$AE$1:$AE$373,0),0) -> 4 | G5: =IF($F5=0,"",IF(ISNUMBER(INDEX(Data!D$1:D$373,$F5)),INDEX(Data!D$1:D$373,$F5),"")) -> 108.4 | H5: =IF($F5=0,"",IF(ISNUMBER(INDEX(Data!E$1:E$373,$F5)),INDEX(Data!E$1:E$373,$F5),"")) -> 107.3 | I5: =IF($F5=0,"",IF(ISNUMBER(INDEX(Data!F$1:F$373,$F5)),INDEX(Data!F$1:F$373,$F5),"")) -> 110 | J5: =IF($F5=0,"",IF(ISNUMBER(INDEX(Data!G$1:G$373,$F5)),INDEX(Data!G$1:G$373,$F5),"")) -> 104.4 | K5: =IF($F5=0,"",IF(ISNUMBER(INDEX(Data!H$1:H$373,$F5)),INDEX(Data!H$1:H$373,$F5),"")) -> 105.1 | L5: =IF($F5=0,"",IF(ISNUMBER(INDEX(Data!I$1:I$373,$F5)),INDEX(Data!I$1:I$373,$F5),"")) -> 103.2 | M5: =IF($F5=0,"",IF(ISNUMBER(INDEX(Data!J$1:J$373,$F5)),INDEX(Data!J$1:J$373,$F5),"")) -> 102.2 | N5: =IF($F5=0,"",IF(ISNUMBER(INDEX(Data!K$1:K$373,$F5)),INDEX(Data!K$1:K$373,$F5),"")) -> 106 | ... AG5: =IF($F5=0,"",IF(ISNUMBER(INDEX(Data!AD$1:AD$373,$F5)),INDEX(Data!AD$1:AD$373,$F5),"")) -> 104.6
A6: 2013 | B6: 2 | C6: February | D6: =DATE(A6,B6,1) -> 41306 | E6: ="Rural+Urban|"&A6&"|"&C6 -> Rural+Urban|2013|February | F6: =IFERROR(MATCH(E6,Data!$AE$1:$AE$373,0),0) -> 7 | G6: =IF($F6=0,"",IF(ISNUMBER(INDEX(Data!D$1:D$373,$F6)),INDEX(Data!D$1:D$373,$F6),"")) -> 110.4 | H6: =IF($F6=0,"",IF(ISNUMBER(INDEX(Data!E$1:E$373,$F6)),INDEX(Data!E$1:E$373,$F6),"")) -> 110.2 | I6: =IF($F6=0,"",IF(ISNUMBER(INDEX(Data!F$1:F$373,$F6)),INDEX(Data!F$1:F$373,$F6),"")) -> 112.8 | J6: =IF($F6=0,"",IF(ISNUMBER(INDEX(Data!G$1:G$373,$F6)),INDEX(Data!G$1:G$373,$F6),"")) -> 104.9 | K6: =IF($F6=0,"",IF(ISNUMBER(INDEX(Data!H$1:H$373,$F6)),INDEX(Data!H$1:H$373,$F6),"")) -> 105.5 | L6: =IF($F6=0,"",IF(ISNUMBER(INDEX(Data!I$1:I$373,$F6)),INDEX(Data!I$1:I$373,$F6),"")) -> 103.6 | M6: =IF($F6=0,"",IF(ISNUMBER(INDEX(Data!J$1:J$373,$F6)),INDEX(Data!J$1:J$373,$F6),"")) -> 103.2 | N6: =IF($F6=0,"",IF(ISNUMBER(INDEX(Data!K$1:K$373,$F6)),INDEX(Data!K$1:K$373,$F6),"")) -> 105.3 | ... AG6: =IF($F6=0,"",IF(ISNUMBER(INDEX(Data!AD$1:AD$373,$F6)),INDEX(Data!AD$1:AD$373,$F6),"")) -> 105.3
A7: 2013 | B7: 3 | C7: March | D7: =DATE(A7,B7,1) -> 41334 | E7: ="Rural+Urban|"&A7&"|"&C7 -> Rural+Urban|2013|March | F7: =IFERROR(MATCH(E7,Data!$AE$1:$AE$373,0),0) -> 10 | G7: =IF($F7=0,"",IF(ISNUMBER(INDEX(Data!D$1:D$373,$F7)),INDEX(Data!D$1:D$373,$F7),"")) -> 111.4 | H7: =IF($F7=0,"",IF(ISNUMBER(INDEX(Data!E$1:E$373,$F7)),INDEX(Data!E$1:E$373,$F7),"")) -> 109.7 | I7: =IF($F7=0,"",IF(ISNUMBER(INDEX(Data!F$1:F$373,$F7)),INDEX(Data!F$1:F$373,$F7),"")) -> 111.2 | J7: =IF($F7=0,"",IF(ISNUMBER(INDEX(Data!G$1:G$373,$F7)),INDEX(Data!G$1:G$373,$F7),"")) -> 105.1 | K7: =IF($F7=0,"",IF(ISNUMBER(INDEX(Data!H$1:H$373,$F7)),INDEX(Data!H$1:H$373,$F7),"")) -> 104.9 | L7: =IF($F7=0,"",IF(ISNUMBER(INDEX(Data!I$1:I$373,$F7)),INDEX(Data!I$1:I$373,$F7),"")) -> 105.3 | M7: =IF($F7=0,"",IF(ISNUMBER(INDEX(Data!J$1:J$373,$F7)),INDEX(Data!J$1:J$373,$F7),"")) -> 102.2 | N7: =IF($F7=0,"",IF(ISNUMBER(INDEX(Data!K$1:K$373,$F7)),INDEX(Data!K$1:K$373,$F7),"")) -> 105 | ... AG7: =IF($F7=0,"",IF(ISNUMBER(INDEX(Data!AD$1:AD$373,$F7)),INDEX(Data!AD$1:AD$373,$F7),"")) -> 105.5
A8: 2013 | B8: 4 | C8: April | D8: =DATE(A8,B8,1) -> 41365 | E8: ="Rural+Urban|"&A8&"|"&C8 -> Rural+Urban|2013|April | F8: =IFERROR(MATCH(E8,Data!$AE$1:$AE$373,0),0) -> 13 | G8: =IF($F8=0,"",IF(ISNUMBER(INDEX(Data!D$1:D$373,$F8)),INDEX(Data!D$1:D$373,$F8),"")) -> 111.6 | H8: =IF($F8=0,"",IF(ISNUMBER(INDEX(Data!E$1:E$373,$F8)),INDEX(Data!E$1:E$373,$F8),"")) -> 110.9 | I8: =IF($F8=0,"",IF(ISNUMBER(INDEX(Data!F$1:F$373,$F8)),INDEX(Data!F$1:F$373,$F8),"")) -> 106.6 | J8: =IF($F8=0,"",IF(ISNUMBER(INDEX(Data!G$1:G$373,$F8)),INDEX(Data!G$1:G$373,$F8),"")) -> 105.7 | K8: =IF($F8=0,"",IF(ISNUMBER(INDEX(Data!H$1:H$373,$F8)),INDEX(Data!H$1:H$373,$F8),"")) -> 104.4 | L8: =IF($F8=0,"",IF(ISNUMBER(INDEX(Data!I$1:I$373,$F8)),INDEX(Data!I$1:I$373,$F8),"")) -> 108.9 | M8: =IF($F8=0,"",IF(ISNUMBER(INDEX(Data!J$1:J$373,$F8)),INDEX(Data!J$1:J$373,$F8),"")) -> 105.5 | N8: =IF($F8=0,"",IF(ISNUMBER(INDEX(Data!K$1:K$373,$F8)),INDEX(Data!K$1:K$373,$F8),"")) -> 105.3 | ... AG8: =IF($F8=0,"",IF(ISNUMBER(INDEX(Data!AD$1:AD$373,$F8)),INDEX(Data!AD$1:AD$373,$F8),"")) -> 106.1
A9: 2013 | B9: 5 | C9: May | D9: =DATE(A9,B9,1) -> 41395 | E9: ="Rural+Urban|"&A9&"|"&C9 -> Rural+Urban|2013|May | F9: =IFERROR(MATCH(E9,Data!$AE$1:$AE$373,0),0) -> 16 | G9: =IF($F9=0,"",IF(ISNUMBER(INDEX(Data!D$1:D$373,$F9)),INDEX(Data!D$1:D$373,$F9),"")) -> 112.3 | H9: =IF($F9=0,"",IF(ISNUMBER(INDEX(Data!E$1:E$373,$F9)),INDEX(Data!E$1:E$373,$F9),"")) -> 111.3 | I9: =IF($F9=0,"",IF(ISNUMBER(INDEX(Data!F$1:F$373,$F9)),INDEX(Data!F$1:F$373,$F9),"")) -> 104.7 | J9: =IF($F9=0,"",IF(ISNUMBER(INDEX(Data!G$1:G$373,$F9)),INDEX(Data!G$1:G$373,$F9),"")) -> 106.8 | K9: =IF($F9=0,"",IF(ISNUMBER(INDEX(Data!H$1:H$373,$F9)),INDEX(Data!H$1:H$373,$F9),"")) -> 103.9 | L9: =IF($F9=0,"",IF(ISNUMBER(INDEX(Data!I$1:I$373,$F9)),INDEX(Data!I$1:I$373,$F9),"")) -> 109.3 | M9: =IF($F9=0,"",IF(ISNUMBER(INDEX(Data!J$1:J$373,$F9)),INDEX(Data!J$1:J$373,$F9),"")) -> 112.9 | N9: =IF($F9=0,"",IF(ISNUMBER(INDEX(Data!K$1:K$373,$F9)),INDEX(Data!K$1:K$373,$F9),"")) -> 105.8 | ... AG9: =IF($F9=0,"",IF(ISNUMBER(INDEX(Data!AD$1:AD$373,$F9)),INDEX(Data!AD$1:AD$373,$F9),"")) -> 106.9
A10: 2013 | B10: 6 | C10: June | D10: =DATE(A10,B10,1) -> 41426 | E10: ="Rural+Urban|"&A10&"|"&C10 -> Rural+Urban|2013|June | F10: =IFERROR(MATCH(E10,Data!$AE$1:$AE$373,0),0) -> 19 | G10: =IF($F10=0,"",IF(ISNUMBER(INDEX(Data!D$1:D$373,$F10)),INDEX(Data!D$1:D$373,$F10),"")) -> 113.8 | H10: =IF($F10=0,"",IF(ISNUMBER(INDEX(Data!E$1:E$373,$F10)),INDEX(Data!E$1:E$373,$F10),"")) -> 114.9 | I10: =IF($F10=0,"",IF(ISNUMBER(INDEX(Data!F$1:F$373,$F10)),INDEX(Data!F$1:F$373,$F10),"")) -> 109.8 | J10: =IF($F10=0,"",IF(ISNUMBER(INDEX(Data!G$1:G$373,$F10)),INDEX(Data!G$1:G$373,$F10),"")) -> 107.9 | K10: =IF($F10=0,"",IF(ISNUMBER(INDEX(Data!H$1:H$373,$F10)),INDEX(Data!H$1:H$373,$F10),"")) -> 104.2 | L10: =IF($F10=0,"",IF(ISNUMBER(INDEX(Data!I$1:I$373,$F10)),INDEX(Data!I$1:I$373,$F10),"")) -> 110.7 | M10: =IF($F10=0,"",IF(ISNUMBER(INDEX(Data!J$1:J$373,$F10)),INDEX(Data!J$1:J$373,$F10),"")) -> 126.7 | N10: =IF($F10=0,"",IF(ISNUMBER(INDEX(Data!K$1:K$373,$F10)),INDEX(Data!K$1:K$373,$F10),"")) -> 106.3 | ... AG10: =IF($F10=0,"",IF(ISNUMBER(INDEX(Data!AD$1:AD$373,$F10)),INDEX(Data!AD$1:AD$373,$F10),"")) -> 109.3
A11: 2013 | B11: 7 | C11: July | D11: =DATE(A11,B11,1) -> 41456 | E11: ="Rural+Urban|"&A11&"|"&C11 -> Rural+Urban|2013|July | F11: =IFERROR(MATCH(E11,Data!$AE$1:$AE$373,0),0) -> 22 | G11: =IF($F11=0,"",IF(ISNUMBER(INDEX(Data!D$1:D$373,$F11)),INDEX(Data!D$1:D$373,$F11),"")) -> 114.8 | H11: =IF($F11=0,"",IF(ISNUMBER(INDEX(Data!E$1:E$373,$F11)),INDEX(Data!E$1:E$373,$F11),"")) -> 116.4 | I11: =IF($F11=0,"",IF(ISNUMBER(INDEX(Data!F$1:F$373,$F11)),INDEX(Data!F$1:F$373,$F11),"")) -> 111.9 | J11: =IF($F11=0,"",IF(ISNUMBER(INDEX(Data!G$1:G$373,$F11)),INDEX(Data!G$1:G$373,$F11),"")) -> 108.9 | K11: =IF($F11=0,"",IF(ISNUMBER(INDEX(Data!H$1:H$373,$F11)),INDEX(Data!H$1:H$373,$F11),"")) -> 104.3 | L11: =IF($F11=0,"",IF(ISNUMBER(INDEX(Data!I$1:I$373,$F11)),INDEX(Data!I$1:I$373,$F11),"")) -> 111.7 | M11: =IF($F11=0,"",IF(ISNUMBER(INDEX(Data!J$1:J$373,$F11)),INDEX(Data!J$1:J$373,$F11),"")) -> 140 | N11: =IF($F11=0,"",IF(ISNUMBER(INDEX(Data!K$1:K$373,$F11)),INDEX(Data!K$1:K$373,$F11),"")) -> 106.4 | ... AG11: =IF($F11=0,"",IF(ISNUMBER(INDEX(Data!AD$1:AD$373,$F11)),INDEX(Data!AD$1:AD$373,$F11),"")) -> 111
A12: 2013 | B12: 8 | C12: August | D12: =DATE(A12,B12,1) -> 41487 | E12: ="Rural+Urban|"&A12&"|"&C12 -> Rural+Urban|2013|August | F12: =IFERROR(MATCH(E12,Data!$AE$1:$AE$373,0),0) -> 25 | G12: =IF($F12=0,"",IF(ISNUMBER(INDEX(Data!D$1:D$373,$F12)),INDEX(Data!D$1:D$373,$F12),"")) -> 115.6 | H12: =IF($F12=0,"",IF(ISNUMBER(INDEX(Data!E$1:E$373,$F12)),INDEX(Data!E$1:E$373,$F12),"")) -> 117.2 | I12: =IF($F12=0,"",IF(ISNUMBER(INDEX(Data!F$1:F$373,$F12)),INDEX(Data!F$1:F$373,$F12),"")) -> 111.7 | J12: =IF($F12=0,"",IF(ISNUMBER(INDEX(Data!G$1:G$373,$F12)),INDEX(Data!G$1:G$373,$F12),"")) -> 109.6 | K12: =IF($F12=0,"",IF(ISNUMBER(INDEX(Data!H$1:H$373,$F12)),INDEX(Data!H$1:H$373,$F12),"")) -> 104.5 | L12: =IF($F12=0,"",IF(ISNUMBER(INDEX(Data!I$1:I$373,$F12)),INDEX(Data!I$1:I$373,$F12),"")) -> 109.8 | M12: =IF($F12=0,"",IF(ISNUMBER(INDEX(Data!J$1:J$373,$F12)),INDEX(Data!J$1:J$373,$F12),"")) -> 151.8 | N12: =IF($F12=0,"",IF(ISNUMBER(INDEX(Data!K$1:K$373,$F12)),INDEX(Data!K$1:K$373,$F12),"")) -> 106.5 | ... AG12: =IF($F12=0,"",IF(ISNUMBER(INDEX(Data!AD$1:AD$373,$F12)),INDEX(Data!AD$1:AD$373,$F12),"")) -> 112.4
A13: 2013 | B13: 9 | C13: September | D13: =DATE(A13,B13,1) -> 41518 | E13: ="Rural+Urban|"&A13&"|"&C13 -> Rural+Urban|2013|September | F13: =IFERROR(MATCH(E13,Data!$AE$1:$AE$373,0),0) -> 28 | G13: =IF($F13=0,"",IF(ISNUMBER(INDEX(Data!D$1:D$373,$F13)),INDEX(Data!D$1:D$373,$F13),"")) -> 116.4 | H13: =IF($F13=0,"",IF(ISNUMBER(INDEX(Data!E$1:E$373,$F13)),INDEX(Data!E$1:E$373,$F13),"")) -> 116.9 | I13: =IF($F13=0,"",IF(ISNUMBER(INDEX(Data!F$1:F$373,$F13)),INDEX(Data!F$1:F$373,$F13),"")) -> 112.3 | J13: =IF($F13=0,"",IF(ISNUMBER(INDEX(Data!G$1:G$373,$F13)),INDEX(Data!G$1:G$373,$F13),"")) -> 110.5 | K13: =IF($F13=0,"",IF(ISNUMBER(INDEX(Data!H$1:H$373,$F13)),INDEX(Data!H$1:H$373,$F13),"")) -> 105.3 | L13: =IF($F13=0,"",IF(ISNUMBER(INDEX(Data!I$1:I$373,$F13)),INDEX(Data!I$1:I$373,$F13),"")) -> 107.3 | M13: =IF($F13=0,"",IF(ISNUMBER(INDEX(Data!J$1:J$373,$F13)),INDEX(Data!J$1:J$373,$F13),"")) -> 160.9 | N13: =IF($F13=0,"",IF(ISNUMBER(INDEX(Data!K$1:K$373,$F13)),INDEX(Data!K$1:K$373,$F13),"")) -> 107.1 | ... AG13: =IF($F13=0,"",IF(ISNUMBER(INDEX(Data!AD$1:AD$373,$F13)),INDEX(Data!AD$1:AD$373,$F13),"")) -> 113.7
A14: 2013 | B14: 10 | C14: October | D14: =DATE(A14,B14,1) -> 41548 | E14: ="Rural+Urban|"&A14&"|"&C14 -> Rural+Urban|2013|October | F14: =IFERROR(MATCH(E14,Data!$AE$1:$AE$373,0),0) -> 31 | G14: =IF($F14=0,"",IF(ISNUMBER(INDEX(Data!D$1:D$373,$F14)),INDEX(Data!D$1:D$373,$F14),"")) -> 117.1 | H14: =IF($F14=0,"",IF(ISNUMBER(INDEX(Data!E$1:E$373,$F14)),INDEX(Data!E$1:E$373,$F14),"")) -> 116.3 | I14: =IF($F14=0,"",IF(ISNUMBER(INDEX(Data!F$1:F$373,$F14)),INDEX(Data!F$1:F$373,$F14),"")) -> 113.3 | J14: =IF($F14=0,"",IF(ISNUMBER(INDEX(Data!G$1:G$373,$F14)),INDEX(Data!G$1:G$373,$F14),"")) -> 111.2 | K14: =IF($F14=0,"",IF(ISNUMBER(INDEX(Data!H$1:H$373,$F14)),INDEX(Data!H$1:H$373,$F14),"")) -> 105.7 | L14: =IF($F14=0,"",IF(ISNUMBER(INDEX(Data!I$1:I$373,$F14)),INDEX(Data!I$1:I$373,$F14),"")) -> 109.9 | M14: =IF($F14=0,"",IF(ISNUMBER(INDEX(Data!J$1:J$373,$F14)),INDEX(Data!J$1:J$373,$F14),"")) -> 171.2 | N14: =IF($F14=0,"",IF(ISNUMBER(INDEX(Data!K$1:K$373,$F14)),INDEX(Data!K$1:K$373,$F14),"")) -> 107.3 | ... AG14: =IF($F14=0,"",IF(ISNUMBER(INDEX(Data!AD$1:AD$373,$F14)),INDEX(Data!AD$1:AD$373,$F14),"")) -> 114.8
A15: 2013 | B15: 11 | C15: November | D15: =DATE(A15,B15,1) -> 41579 | E15: ="Rural+Urban|"&A15&"|"&C15 -> Rural+Urban|2013|November | F15: =IFERROR(MATCH(E15,Data!$AE$1:$AE$373,0),0) -> 34 | G15: =IF($F15=0,"",IF(ISNUMBER(INDEX(Data!D$1:D$373,$F15)),INDEX(Data!D$1:D$373,$F15),"")) -> 118.1 | H15: =IF($F15=0,"",IF(ISNUMBER(INDEX(Data!E$1:E$373,$F15)),INDEX(Data!E$1:E$373,$F15),"")) -> 115.4 | I15: =IF($F15=0,"",IF(ISNUMBER(INDEX(Data!F$1:F$373,$F15)),INDEX(Data!F$1:F$373,$F15),"")) -> 118.7 | J15: =IF($F15=0,"",IF(ISNUMBER(INDEX(Data!G$1:G$373,$F15)),INDEX(Data!G$1:G$373,$F15),"")) -> 112.5 | K15: =IF($F15=0,"",IF(ISNUMBER(INDEX(Data!H$1:H$373,$F15)),INDEX(Data!H$1:H$373,$F15),"")) -> 106.8 | L15: =IF($F15=0,"",IF(ISNUMBER(INDEX(Data!I$1:I$373,$F15)),INDEX(Data!I$1:I$373,$F15),"")) -> 113.5 | M15: =IF($F15=0,"",IF(ISNUMBER(INDEX(Data!J$1:J$373,$F15)),INDEX(Data!J$1:J$373,$F15),"")) -> 183.1 | N15: =IF($F15=0,"",IF(ISNUMBER(INDEX(Data!K$1:K$373,$F15)),INDEX(Data!K$1:K$373,$F15),"")) -> 108.2 | ... AG15: =IF($F15=0,"",IF(ISNUMBER(INDEX(Data!AD$1:AD$373,$F15)),INDEX(Data!AD$1:AD$373,$F15),"")) -> 116.3
A16: 2013 | B16: 12 | C16: December | D16: =DATE(A16,B16,1) -> 41609 | E16: ="Rural+Urban|"&A16&"|"&C16 -> Rural+Urban|2013|December | F16: =IFERROR(MATCH(E16,Data!$AE$1:$AE$373,0),0) -> 37 | G16: =IF($F16=0,"",IF(ISNUMBER(INDEX(Data!D$1:D$373,$F16)),INDEX(Data!D$1:D$373,$F16),"")) -> 119.1 | H16: =IF($F16=0,"",IF(ISNUMBER(INDEX(Data!E$1:E$373,$F16)),INDEX(Data!E$1:E$373,$F16),"")) -> 116.7 | I16: =IF($F16=0,"",IF(ISNUMBER(INDEX(Data!F$1:F$373,$F16)),INDEX(Data!F$1:F$373,$F16),"")) -> 123.5 | J16: =IF($F16=0,"",IF(ISNUMBER(INDEX(Data!G$1:G$373,$F16)),INDEX(Data!G$1:G$373,$F16),"")) -> 113.4 | K16: =IF($F16=0,"",IF(ISNUMBER(INDEX(Data!H$1:H$373,$F16)),INDEX(Data!H$1:H$373,$F16),"")) -> 107.3 | L16: =IF($F16=0,"",IF(ISNUMBER(INDEX(Data!I$1:I$373,$F16)),INDEX(Data!I$1:I$373,$F16),"")) -> 113.3 | M16: =IF($F16=0,"",IF(ISNUMBER(INDEX(Data!J$1:J$373,$F16)),INDEX(Data!J$1:J$373,$F16),"")) -> 145.4 | N16: =IF($F16=0,"",IF(ISNUMBER(INDEX(Data!K$1:K$373,$F16)),INDEX(Data!K$1:K$373,$F16),"")) -> 108.7 | ... AG16: =IF($F16=0,"",IF(ISNUMBER(INDEX(Data!AD$1:AD$373,$F16)),INDEX(Data!AD$1:AD$373,$F16),"")) -> 114.5
... A129: 2023 | B129: 5 | C129: May | D129: =DATE(A129,B129,1) -> 45047 | E129: ="Rural+Urban|"&A129&"|"&C129 -> Rural+Urban|2023|May | F129: =IFERROR(MATCH(E129,Data!$AE$1:$AE$373,0),0) -> 373 | G129: =IF($F129=0,"",IF(ISNUMBER(INDEX(Data!D$1:D$373,$F129)),INDEX(Data!D$1:D$373,$F129),"")) -> 173.7 | H129: =IF($F129=0,"",IF(ISNUMBER(INDEX(Data!E$1:E$373,$F129)),INDEX(Data!E$1:E$373,$F129),"")) -> 214.3 | I129: =IF($F129=0,"",IF(ISNUMBER(INDEX(Data!F$1:F$373,$F129)),INDEX(Data!F$1:F$373,$F129),"")) -> 173.2 | J129: =IF($F129=0,"",IF(ISNUMBER(INDEX(Data!G$1:G$373,$F129)),INDEX(Data!G$1:G$373,$F129),"")) -> 179.5 | K129: =IF($F129=0,"",IF(ISNUMBER(INDEX(Data!H$1:H$373,$F129)),INDEX(Data!H$1:H$373,$F129),"")) -> 170 | L129: =IF($F129=0,"",IF(ISNUMBER(INDEX(Data!I$1:I$373,$F129)),INDEX(Data!I$1:I$373,$F129),"")) -> 172.2 | M129: =IF($F129=0,"",IF(ISNUMBER(INDEX(Data!J$1:J$373,$F129)),INDEX(Data!J$1:J$373,$F129),"")) -> 161 | N129: =IF($F129=0,"",IF(ISNUMBER(INDEX(Data!K$1:K$373,$F129)),INDEX(Data!K$1:K$373,$F129),"")) -> 175.6 | ... AG129: =IF($F129=0,"",IF(ISNUMBER(INDEX(Data!AD$1:AD$373,$F129)),INDEX(Data!AD$1:AD$373,$F129),"")) -> 179.1

Sheet RU_Clean
A1: Rural+Urban index - cleaned (missing values imputed)
A2: Imputation: 1 missing month = average of previous & next month; 2 missing months = straight-line (linear) between neighbours. Last column = equal-weight Food bucket.
A4: Year | B4: MonthNo | C4: Month | D4: Date | E4: # imputed in row | F4: Flag | G4: Cereals and products | H4: Meat and fish | I4: Egg | J4: Milk and products | K4: Oils and fats | L4: Fruits | M4: Vegetables | N4: Pulses and products | O4: Sugar and Confectionery | P4: Spices | Q4: Non-alcoholic beverages | R4: Prepared meals, snacks, sweets etc. | S4: Food and beverages | T4: Pan, tobacco and intoxicants | U4: Clothing | V4: Footwear | W4: Clothing and footwear | X4: Housing | Y4: Fuel and light | Z4: Household goods and services | AA4: Health | AB4: Transport and communication | AC4: Recreation and amusement | AD4: Education | AE4: Personal care and effects | AF4: Miscellaneous | AG4: General index | AH4: Food bucket (sum of 12 food items)
A5: =RU_Raw!A5 -> 2013 | B5: =RU_Raw!B5 -> 1 | C5: =RU_Raw!C5 -> January | D5: =RU_Raw!D5 -> 41275 | E5: =COUNTBLANK(RU_Raw!G5:AG5) -> 0 | F5: =IF(E5>0,"Imputed","") | G5: =IF(ISNUMBER(RU_Raw!G5),RU_Raw!G5,IF(ISNUMBER(RU_Raw!G6),(G4+RU_Raw!G6)/2,IF(ISNUMBER(RU_Raw!G7),G4+(RU_Raw!G7-G4)/3,""))) -> 108.4 | H5: =IF(ISNUMBER(RU_Raw!H5),RU_Raw!H5,IF(ISNUMBER(RU_Raw!H6),(H4+RU_Raw!H6)/2,IF(ISNUMBER(RU_Raw!H7),H4+(RU_Raw!H7-H4)/3,""))) -> 107.3 | I5: =IF(ISNUMBER(RU_Raw!I5),RU_Raw!I5,IF(ISNUMBER(RU_Raw!I6),(I4+RU_Raw!I6)/2,IF(ISNUMBER(RU_Raw!I7),I4+(RU_Raw!I7-I4)/3,""))) -> 110 | J5: =IF(ISNUMBER(RU_Raw!J5),RU_Raw!J5,IF(ISNUMBER(RU_Raw!J6),(J4+RU_Raw!J6)/2,IF(ISNUMBER(RU_Raw!J7),J4+(RU_Raw!J7-J4)/3,""))) -> 104.4 | K5: =IF(ISNUMBER(RU_Raw!K5),RU_Raw!K5,IF(ISNUMBER(RU_Raw!K6),(K4+RU_Raw!K6)/2,IF(ISNUMBER(RU_Raw!K7),K4+(RU_Raw!K7-K4)/3,""))) -> 105.1 | L5: =IF(ISNUMBER(RU_Raw!L5),RU_Raw!L5,IF(ISNUMBER(RU_Raw!L6),(L4+RU_Raw!L6)/2,IF(ISNUMBER(RU_Raw!L7),L4+(RU_Raw!L7-L4)/3,""))) -> 103.2 | M5: =IF(ISNUMBER(RU_Raw!M5),RU_Raw!M5,IF(ISNUMBER(RU_Raw!M6),(M4+RU_Raw!M6)/2,IF(ISNUMBER(RU_Raw!M7),M4+(RU_Raw!M7-M4)/3,""))) -> 102.2 | N5: =IF(ISNUMBER(RU_Raw!N5),RU_Raw!N5,IF(ISNUMBER(RU_Raw!N6),(N4+RU_Raw!N6)/2,IF(ISNUMBER(RU_Raw!N7),N4+(RU_Raw!N7-N4)/3,""))) -> 106 | ... AG5: =IF(ISNUMBER(RU_Raw!AG5),RU_Raw!AG5,IF(ISNUMBER(RU_Raw!AG6),(AG4+RU_Raw!AG6)/2,IF(ISNUMBER(RU_Raw!AG7),AG4+(RU_Raw!AG7-AG4)/3,""))) -> 104.6 | AH5: =SUM(G5:R5) -> 1267.7
A6: =RU_Raw!A6 -> 2013 | B6: =RU_Raw!B6 -> 2 | C6: =RU_Raw!C6 -> February | D6: =RU_Raw!D6 -> 41306 | E6: =COUNTBLANK(RU_Raw!G6:AG6) -> 0 | F6: =IF(E6>0,"Imputed","") | G6: =IF(ISNUMBER(RU_Raw!G6),RU_Raw!G6,IF(ISNUMBER(RU_Raw!G7),(G5+RU_Raw!G7)/2,IF(ISNUMBER(RU_Raw!G8),G5+(RU_Raw!G8-G5)/3,""))) -> 110.4 | H6: =IF(ISNUMBER(RU_Raw!H6),RU_Raw!H6,IF(ISNUMBER(RU_Raw!H7),(H5+RU_Raw!H7)/2,IF(ISNUMBER(RU_Raw!H8),H5+(RU_Raw!H8-H5)/3,""))) -> 110.2 | I6: =IF(ISNUMBER(RU_Raw!I6),RU_Raw!I6,IF(ISNUMBER(RU_Raw!I7),(I5+RU_Raw!I7)/2,IF(ISNUMBER(RU_Raw!I8),I5+(RU_Raw!I8-I5)/3,""))) -> 112.8 | J6: =IF(ISNUMBER(RU_Raw!J6),RU_Raw!J6,IF(ISNUMBER(RU_Raw!J7),(J5+RU_Raw!J7)/2,IF(ISNUMBER(RU_Raw!J8),J5+(RU_Raw!J8-J5)/3,""))) -> 104.9 | K6: =IF(ISNUMBER(RU_Raw!K6),RU_Raw!K6,IF(ISNUMBER(RU_Raw!K7),(K5+RU_Raw!K7)/2,IF(ISNUMBER(RU_Raw!K8),K5+(RU_Raw!K8-K5)/3,""))) -> 105.5 | L6: =IF(ISNUMBER(RU_Raw!L6),RU_Raw!L6,IF(ISNUMBER(RU_Raw!L7),(L5+RU_Raw!L7)/2,IF(ISNUMBER(RU_Raw!L8),L5+(RU_Raw!L8-L5)/3,""))) -> 103.6 | M6: =IF(ISNUMBER(RU_Raw!M6),RU_Raw!M6,IF(ISNUMBER(RU_Raw!M7),(M5+RU_Raw!M7)/2,IF(ISNUMBER(RU_Raw!M8),M5+(RU_Raw!M8-M5)/3,""))) -> 103.2 | N6: =IF(ISNUMBER(RU_Raw!N6),RU_Raw!N6,IF(ISNUMBER(RU_Raw!N7),(N5+RU_Raw!N7)/2,IF(ISNUMBER(RU_Raw!N8),N5+(RU_Raw!N8-N5)/3,""))) -> 105.3 | ... AG6: =IF(ISNUMBER(RU_Raw!AG6),RU_Raw!AG6,IF(ISNUMBER(RU_Raw!AG7),(AG5+RU_Raw!AG7)/2,IF(ISNUMBER(RU_Raw!AG8),AG5+(RU_Raw!AG8-AG5)/3,""))) -> 105.3 | AH6: =SUM(G6:R6) -> 1277.6
A7: =RU_Raw!A7 -> 2013 | B7: =RU_Raw!B7 -> 3 | C7: =RU_Raw!C7 -> March | D7: =RU_Raw!D7 -> 41334 | E7: =COUNTBLANK(RU_Raw!G7:AG7) -> 0 | F7: =IF(E7>0,"Imputed","") | G7: =IF(ISNUMBER(RU_Raw!G7),RU_Raw!G7,IF(ISNUMBER(RU_Raw!G8),(G6+RU_Raw!G8)/2,IF(ISNUMBER(RU_Raw!G9),G6+(RU_Raw!G9-G6)/3,""))) -> 111.4 | H7: =IF(ISNUMBER(RU_Raw!H7),RU_Raw!H7,IF(ISNUMBER(RU_Raw!H8),(H6+RU_Raw!H8)/2,IF(ISNUMBER(RU_Raw!H9),H6+(RU_Raw!H9-H6)/3,""))) -> 109.7 | I7: =IF(ISNUMBER(RU_Raw!I7),RU_Raw!I7,IF(ISNUMBER(RU_Raw!I8),(I6+RU_Raw!I8)/2,IF(ISNUMBER(RU_Raw!I9),I6+(RU_Raw!I9-I6)/3,""))) -> 111.2 | J7: =IF(ISNUMBER(RU_Raw!J7),RU_Raw!J7,IF(ISNUMBER(RU_Raw!J8),(J6+RU_Raw!J8)/2,IF(ISNUMBER(RU_Raw!J9),J6+(RU_Raw!J9-J6)/3,""))) -> 105.1 | K7: =IF(ISNUMBER(RU_Raw!K7),RU_Raw!K7,IF(ISNUMBER(RU_Raw!K8),(K6+RU_Raw!K8)/2,IF(ISNUMBER(RU_Raw!K9),K6+(RU_Raw!K9-K6)/3,""))) -> 104.9 | L7: =IF(ISNUMBER(RU_Raw!L7),RU_Raw!L7,IF(ISNUMBER(RU_Raw!L8),(L6+RU_Raw!L8)/2,IF(ISNUMBER(RU_Raw!L9),L6+(RU_Raw!L9-L6)/3,""))) -> 105.3 | M7: =IF(ISNUMBER(RU_Raw!M7),RU_Raw!M7,IF(ISNUMBER(RU_Raw!M8),(M6+RU_Raw!M8)/2,IF(ISNUMBER(RU_Raw!M9),M6+(RU_Raw!M9-M6)/3,""))) -> 102.2 | N7: =IF(ISNUMBER(RU_Raw!N7),RU_Raw!N7,IF(ISNUMBER(RU_Raw!N8),(N6+RU_Raw!N8)/2,IF(ISNUMBER(RU_Raw!N9),N6+(RU_Raw!N9-N6)/3,""))) -> 105 | ... AG7: =IF(ISNUMBER(RU_Raw!AG7),RU_Raw!AG7,IF(ISNUMBER(RU_Raw!AG8),(AG6+RU_Raw!AG8)/2,IF(ISNUMBER(RU_Raw!AG9),AG6+(RU_Raw!AG9-AG6)/3,""))) -> 105.5 | AH7: =SUM(G7:R7) -> 1277.1
A8: =RU_Raw!A8 -> 2013 | B8: =RU_Raw!B8 -> 4 | C8: =RU_Raw!C8 -> April | D8: =RU_Raw!D8 -> 41365 | E8: =COUNTBLANK(RU_Raw!G8:AG8) -> 0 | F8: =IF(E8>0,"Imputed","") | G8: =IF(ISNUMBER(RU_Raw!G8),RU_Raw!G8,IF(ISNUMBER(RU_Raw!G9),(G7+RU_Raw!G9)/2,IF(ISNUMBER(RU_Raw!G10),G7+(RU_Raw!G10-G7)/3,""))) -> 111.6 | H8: =IF(ISNUMBER(RU_Raw!H8),RU_Raw!H8,IF(ISNUMBER(RU_Raw!H9),(H7+RU_Raw!H9)/2,IF(ISNUMBER(RU_Raw!H10),H7+(RU_Raw!H10-H7)/3,""))) -> 110.9 | I8: =IF(ISNUMBER(RU_Raw!I8),RU_Raw!I8,IF(ISNUMBER(RU_Raw!I9),(I7+RU_Raw!I9)/2,IF(ISNUMBER(RU_Raw!I10),I7+(RU_Raw!I10-I7)/3,""))) -> 106.6 | J8: =IF(ISNUMBER(RU_Raw!J8),RU_Raw!J8,IF(ISNUMBER(RU_Raw!J9),(J7+RU_Raw!J9)/2,IF(ISNUMBER(RU_Raw!J10),J7+(RU_Raw!J10-J7)/3,""))) -> 105.7 | K8: =IF(ISNUMBER(RU_Raw!K8),RU_Raw!K8,IF(ISNUMBER(RU_Raw!K9),(K7+RU_Raw!K9)/2,IF(ISNUMBER(RU_Raw!K10),K7+(RU_Raw!K10-K7)/3,""))) -> 104.4 | L8: =IF(ISNUMBER(RU_Raw!L8),RU_Raw!L8,IF(ISNUMBER(RU_Raw!L9),(L7+RU_Raw!L9)/2,IF(ISNUMBER(RU_Raw!L10),L7+(RU_Raw!L10-L7)/3,""))) -> 108.9 | M8: =IF(ISNUMBER(RU_Raw!M8),RU_Raw!M8,IF(ISNUMBER(RU_Raw!M9),(M7+RU_Raw!M9)/2,IF(ISNUMBER(RU_Raw!M10),M7+(RU_Raw!M10-M7)/3,""))) -> 105.5 | N8: =IF(ISNUMBER(RU_Raw!N8),RU_Raw!N8,IF(ISNUMBER(RU_Raw!N9),(N7+RU_Raw!N9)/2,IF(ISNUMBER(RU_Raw!N10),N7+(RU_Raw!N10-N7)/3,""))) -> 105.3 | ... AG8: =IF(ISNUMBER(RU_Raw!AG8),RU_Raw!AG8,IF(ISNUMBER(RU_Raw!AG9),(AG7+RU_Raw!AG9)/2,IF(ISNUMBER(RU_Raw!AG10),AG7+(RU_Raw!AG10-AG7)/3,""))) -> 106.1 | AH8: =SUM(G8:R8) -> 1282.5
A9: =RU_Raw!A9 -> 2013 | B9: =RU_Raw!B9 -> 5 | C9: =RU_Raw!C9 -> May | D9: =RU_Raw!D9 -> 41395 | E9: =COUNTBLANK(RU_Raw!G9:AG9) -> 0 | F9: =IF(E9>0,"Imputed","") | G9: =IF(ISNUMBER(RU_Raw!G9),RU_Raw!G9,IF(ISNUMBER(RU_Raw!G10),(G8+RU_Raw!G10)/2,IF(ISNUMBER(RU_Raw!G11),G8+(RU_Raw!G11-G8)/3,""))) -> 112.3 | H9: =IF(ISNUMBER(RU_Raw!H9),RU_Raw!H9,IF(ISNUMBER(RU_Raw!H10),(H8+RU_Raw!H10)/2,IF(ISNUMBER(RU_Raw!H11),H8+(RU_Raw!H11-H8)/3,""))) -> 111.3 | I9: =IF(ISNUMBER(RU_Raw!I9),RU_Raw!I9,IF(ISNUMBER(RU_Raw!I10),(I8+RU_Raw!I10)/2,IF(ISNUMBER(RU_Raw!I11),I8+(RU_Raw!I11-I8)/3,""))) -> 104.7 | J9: =IF(ISNUMBER(RU_Raw!J9),RU_Raw!J9,IF(ISNUMBER(RU_Raw!J10),(J8+RU_Raw!J10)/2,IF(ISNUMBER(RU_Raw!J11),J8+(RU_Raw!J11-J8)/3,""))) -> 106.8 | K9: =IF(ISNUMBER(RU_Raw!K9),RU_Raw!K9,IF(ISNUMBER(RU_Raw!K10),(K8+RU_Raw!K10)/2,IF(ISNUMBER(RU_Raw!K11),K8+(RU_Raw!K11-K8)/3,""))) -> 103.9 | L9: =IF(ISNUMBER(RU_Raw!L9),RU_Raw!L9,IF(ISNUMBER(RU_Raw!L10),(L8+RU_Raw!L10)/2,IF(ISNUMBER(RU_Raw!L11),L8+(RU_Raw!L11-L8)/3,""))) -> 109.3 | M9: =IF(ISNUMBER(RU_Raw!M9),RU_Raw!M9,IF(ISNUMBER(RU_Raw!M10),(M8+RU_Raw!M10)/2,IF(ISNUMBER(RU_Raw!M11),M8+(RU_Raw!M11-M8)/3,""))) -> 112.9 | N9: =IF(ISNUMBER(RU_Raw!N9),RU_Raw!N9,IF(ISNUMBER(RU_Raw!N10),(N8+RU_Raw!N10)/2,IF(ISNUMBER(RU_Raw!N11),N8+(RU_Raw!N11-N8)/3,""))) -> 105.8 | ... AG9: =IF(ISNUMBER(RU_Raw!AG9),RU_Raw!AG9,IF(ISNUMBER(RU_Raw!AG10),(AG8+RU_Raw!AG10)/2,IF(ISNUMBER(RU_Raw!AG11),AG8+(RU_Raw!AG11-AG8)/3,""))) -> 106.9 | AH9: =SUM(G9:R9) -> 1293
A10: =RU_Raw!A10 -> 2013 | B10: =RU_Raw!B10 -> 6 | C10: =RU_Raw!C10 -> June | D10: =RU_Raw!D10 -> 41426 | E10: =COUNTBLANK(RU_Raw!G10:AG10) -> 0 | F10: =IF(E10>0,"Imputed","") | G10: =IF(ISNUMBER(RU_Raw!G10),RU_Raw!G10,IF(ISNUMBER(RU_Raw!G11),(G9+RU_Raw!G11)/2,IF(ISNUMBER(RU_Raw!G12),G9+(RU_Raw!G12-G9)/3,""))) -> 113.8 | H10: =IF(ISNUMBER(RU_Raw!H10),RU_Raw!H10,IF(ISNUMBER(RU_Raw!H11),(H9+RU_Raw!H11)/2,IF(ISNUMBER(RU_Raw!H12),H9+(RU_Raw!H12-H9)/3,""))) -> 114.9 | I10: =IF(ISNUMBER(RU_Raw!I10),RU_Raw!I10,IF(ISNUMBER(RU_Raw!I11),(I9+RU_Raw!I11)/2,IF(ISNUMBER(RU_Raw!I12),I9+(RU_Raw!I12-I9)/3,""))) -> 109.8 | J10: =IF(ISNUMBER(RU_Raw!J10),RU_Raw!J10,IF(ISNUMBER(RU_Raw!J11),(J9+RU_Raw!J11)/2,IF(ISNUMBER(RU_Raw!J12),J9+(RU_Raw!J12-J9)/3,""))) -> 107.9 | K10: =IF(ISNUMBER(RU_Raw!K10),RU_Raw!K10,IF(ISNUMBER(RU_Raw!K11),(K9+RU_Raw!K11)/2,IF(ISNUMBER(RU_Raw!K12),K9+(RU_Raw!K12-K9)/3,""))) -> 104.2 | L10: =IF(ISNUMBER(RU_Raw!L10),RU_Raw!L10,IF(ISNUMBER(RU_Raw!L11),(L9+RU_Raw!L11)/2,IF(ISNUMBER(RU_Raw!L12),L9+(RU_Raw!L12-L9)/3,""))) -> 110.7 | M10: =IF(ISNUMBER(RU_Raw!M10),RU_Raw!M10,IF(ISNUMBER(RU_Raw!M11),(M9+RU_Raw!M11)/2,IF(ISNUMBER(RU_Raw!M12),M9+(RU_Raw!M12-M9)/3,""))) -> 126.7 | N10: =IF(ISNUMBER(RU_Raw!N10),RU_Raw!N10,IF(ISNUMBER(RU_Raw!N11),(N9+RU_Raw!N11)/2,IF(ISNUMBER(RU_Raw!N12),N9+(RU_Raw!N12-N9)/3,""))) -> 106.3 | ... AG10: =IF(ISNUMBER(RU_Raw!AG10),RU_Raw!AG10,IF(ISNUMBER(RU_Raw!AG11),(AG9+RU_Raw!AG11)/2,IF(ISNUMBER(RU_Raw!AG12),AG9+(RU_Raw!AG12-AG9)/3,""))) -> 109.3 | AH10: =SUM(G10:R10) -> 1323.8
A11: =RU_Raw!A11 -> 2013 | B11: =RU_Raw!B11 -> 7 | C11: =RU_Raw!C11 -> July | D11: =RU_Raw!D11 -> 41456 | E11: =COUNTBLANK(RU_Raw!G11:AG11) -> 0 | F11: =IF(E11>0,"Imputed","") | G11: =IF(ISNUMBER(RU_Raw!G11),RU_Raw!G11,IF(ISNUMBER(RU_Raw!G12),(G10+RU_Raw!G12)/2,IF(ISNUMBER(RU_Raw!G13),G10+(RU_Raw!G13-G10)/3,""))) -> 114.8 | H11: =IF(ISNUMBER(RU_Raw!H11),RU_Raw!H11,IF(ISNUMBER(RU_Raw!H12),(H10+RU_Raw!H12)/2,IF(ISNUMBER(RU_Raw!H13),H10+(RU_Raw!H13-H10)/3,""))) -> 116.4 | I11: =IF(ISNUMBER(RU_Raw!I11),RU_Raw!I11,IF(ISNUMBER(RU_Raw!I12),(I10+RU_Raw!I12)/2,IF(ISNUMBER(RU_Raw!I13),I10+(RU_Raw!I13-I10)/3,""))) -> 111.9 | J11: =IF(ISNUMBER(RU_Raw!J11),RU_Raw!J11,IF(ISNUMBER(RU_Raw!J12),(J10+RU_Raw!J12)/2,IF(ISNUMBER(RU_Raw!J13),J10+(RU_Raw!J13-J10)/3,""))) -> 108.9 | K11: =IF(ISNUMBER(RU_Raw!K11),RU_Raw!K11,IF(ISNUMBER(RU_Raw!K12),(K10+RU_Raw!K12)/2,IF(ISNUMBER(RU_Raw!K13),K10+(RU_Raw!K13-K10)/3,""))) -> 104.3 | L11: =IF(ISNUMBER(RU_Raw!L11),RU_Raw!L11,IF(ISNUMBER(RU_Raw!L12),(L10+RU_Raw!L12)/2,IF(ISNUMBER(RU_Raw!L13),L10+(RU_Raw!L13-L10)/3,""))) -> 111.7 | M11: =IF(ISNUMBER(RU_Raw!M11),RU_Raw!M11,IF(ISNUMBER(RU_Raw!M12),(M10+RU_Raw!M12)/2,IF(ISNUMBER(RU_Raw!M13),M10+(RU_Raw!M13-M10)/3,""))) -> 140 | N11: =IF(ISNUMBER(RU_Raw!N11),RU_Raw!N11,IF(ISNUMBER(RU_Raw!N12),(N10+RU_Raw!N12)/2,IF(ISNUMBER(RU_Raw!N13),N10+(RU_Raw!N13-N10)/3,""))) -> 106.4 | ... AG11: =IF(ISNUMBER(RU_Raw!AG11),RU_Raw!AG11,IF(ISNUMBER(RU_Raw!AG12),(AG10+RU_Raw!AG12)/2,IF(ISNUMBER(RU_Raw!AG13),AG10+(RU_Raw!AG13-AG10)/3,""))) -> 111 | AH11: =SUM(G11:R11) -> 1346.7
A12: =RU_Raw!A12 -> 2013 | B12: =RU_Raw!B12 -> 8 | C12: =RU_Raw!C12 -> August | D12: =RU_Raw!D12 -> 41487 | E12: =COUNTBLANK(RU_Raw!G12:AG12) -> 0 | F12: =IF(E12>0,"Imputed","") | G12: =IF(ISNUMBER(RU_Raw!G12),RU_Raw!G12,IF(ISNUMBER(RU_Raw!G13),(G11+RU_Raw!G13)/2,IF(ISNUMBER(RU_Raw!G14),G11+(RU_Raw!G14-G11)/3,""))) -> 115.6 | H12: =IF(ISNUMBER(RU_Raw!H12),RU_Raw!H12,IF(ISNUMBER(RU_Raw!H13),(H11+RU_Raw!H13)/2,IF(ISNUMBER(RU_Raw!H14),H11+(RU_Raw!H14-H11)/3,""))) -> 117.2 | I12: =IF(ISNUMBER(RU_Raw!I12),RU_Raw!I12,IF(ISNUMBER(RU_Raw!I13),(I11+RU_Raw!I13)/2,IF(ISNUMBER(RU_Raw!I14),I11+(RU_Raw!I14-I11)/3,""))) -> 111.7 | J12: =IF(ISNUMBER(RU_Raw!J12),RU_Raw!J12,IF(ISNUMBER(RU_Raw!J13),(J11+RU_Raw!J13)/2,IF(ISNUMBER(RU_Raw!J14),J11+(RU_Raw!J14-J11)/3,""))) -> 109.6 | K12: =IF(ISNUMBER(RU_Raw!K12),RU_Raw!K12,IF(ISNUMBER(RU_Raw!K13),(K11+RU_Raw!K13)/2,IF(ISNUMBER(RU_Raw!K14),K11+(RU_Raw!K14-K11)/3,""))) -> 104.5 | L12: =IF(ISNUMBER(RU_Raw!L12),RU_Raw!L12,IF(ISNUMBER(RU_Raw!L13),(L11+RU_Raw!L13)/2,IF(ISNUMBER(RU_Raw!L14),L11+(RU_Raw!L14-L11)/3,""))) -> 109.8 | M12: =IF(ISNUMBER(RU_Raw!M12),RU_Raw!M12,IF(ISNUMBER(RU_Raw!M13),(M11+RU_Raw!M13)/2,IF(ISNUMBER(RU_Raw!M14),M11+(RU_Raw!M14-M11)/3,""))) -> 151.8 | N12: =IF(ISNUMBER(RU_Raw!N12),RU_Raw!N12,IF(ISNUMBER(RU_Raw!N13),(N11+RU_Raw!N13)/2,IF(ISNUMBER(RU_Raw!N14),N11+(RU_Raw!N14-N11)/3,""))) -> 106.5 | ... AG12: =IF(ISNUMBER(RU_Raw!AG12),RU_Raw!AG12,IF(ISNUMBER(RU_Raw!AG13),(AG11+RU_Raw!AG13)/2,IF(ISNUMBER(RU_Raw!AG14),AG11+(RU_Raw!AG14-AG11)/3,""))) -> 112.4 | AH12: =SUM(G12:R12) -> 1360.8
A13: =RU_Raw!A13 -> 2013 | B13: =RU_Raw!B13 -> 9 | C13: =RU_Raw!C13 -> September | D13: =RU_Raw!D13 -> 41518 | E13: =COUNTBLANK(RU_Raw!G13:AG13) -> 0 | F13: =IF(E13>0,"Imputed","") | G13: =IF(ISNUMBER(RU_Raw!G13),RU_Raw!G13,IF(ISNUMBER(RU_Raw!G14),(G12+RU_Raw!G14)/2,IF(ISNUMBER(RU_Raw!G15),G12+(RU_Raw!G15-G12)/3,""))) -> 116.4 | H13: =IF(ISNUMBER(RU_Raw!H13),RU_Raw!H13,IF(ISNUMBER(RU_Raw!H14),(H12+RU_Raw!H14)/2,IF(ISNUMBER(RU_Raw!H15),H12+(RU_Raw!H15-H12)/3,""))) -> 116.9 | I13: =IF(ISNUMBER(RU_Raw!I13),RU_Raw!I13,IF(ISNUMBER(RU_Raw!I14),(I12+RU_Raw!I14)/2,IF(ISNUMBER(RU_Raw!I15),I12+(RU_Raw!I15-I12)/3,""))) -> 112.3 | J13: =IF(ISNUMBER(RU_Raw!J13),RU_Raw!J13,IF(ISNUMBER(RU_Raw!J14),(J12+RU_Raw!J14)/2,IF(ISNUMBER(RU_Raw!J15),J12+(RU_Raw!J15-J12)/3,""))) -> 110.5 | K13: =IF(ISNUMBER(RU_Raw!K13),RU_Raw!K13,IF(ISNUMBER(RU_Raw!K14),(K12+RU_Raw!K14)/2,IF(ISNUMBER(RU_Raw!K15),K12+(RU_Raw!K15-K12)/3,""))) -> 105.3 | L13: =IF(ISNUMBER(RU_Raw!L13),RU_Raw!L13,IF(ISNUMBER(RU_Raw!L14),(L12+RU_Raw!L14)/2,IF(ISNUMBER(RU_Raw!L15),L12+(RU_Raw!L15-L12)/3,""))) -> 107.3 | M13: =IF(ISNUMBER(RU_Raw!M13),RU_Raw!M13,IF(ISNUMBER(RU_Raw!M14),(M12+RU_Raw!M14)/2,IF(ISNUMBER(RU_Raw!M15),M12+(RU_Raw!M15-M12)/3,""))) -> 160.9 | N13: =IF(ISNUMBER(RU_Raw!N13),RU_Raw!N13,IF(ISNUMBER(RU_Raw!N14),(N12+RU_Raw!N14)/2,IF(ISNUMBER(RU_Raw!N15),N12+(RU_Raw!N15-N12)/3,""))) -> 107.1 | ... AG13: =IF(ISNUMBER(RU_Raw!AG13),RU_Raw!AG13,IF(ISNUMBER(RU_Raw!AG14),(AG12+RU_Raw!AG14)/2,IF(ISNUMBER(RU_Raw!AG15),AG12+(RU_Raw!AG15-AG12)/3,""))) -> 113.7 | AH13: =SUM(G13:R13) -> 1373.4
A14: =RU_Raw!A14 -> 2013 | B14: =RU_Raw!B14 -> 10 | C14: =RU_Raw!C14 -> October | D14: =RU_Raw!D14 -> 41548 | E14: =COUNTBLANK(RU_Raw!G14:AG14) -> 0 | F14: =IF(E14>0,"Imputed","") | G14: =IF(ISNUMBER(RU_Raw!G14),RU_Raw!G14,IF(ISNUMBER(RU_Raw!G15),(G13+RU_Raw!G15)/2,IF(ISNUMBER(RU_Raw!G16),G13+(RU_Raw!G16-G13)/3,""))) -> 117.1 | H14: =IF(ISNUMBER(RU_Raw!H14),RU_Raw!H14,IF(ISNUMBER(RU_Raw!H15),(H13+RU_Raw!H15)/2,IF(ISNUMBER(RU_Raw!H16),H13+(RU_Raw!H16-H13)/3,""))) -> 116.3 | I14: =IF(ISNUMBER(RU_Raw!I14),RU_Raw!I14,IF(ISNUMBER(RU_Raw!I15),(I13+RU_Raw!I15)/2,IF(ISNUMBER(RU_Raw!I16),I13+(RU_Raw!I16-I13)/3,""))) -> 113.3 | J14: =IF(ISNUMBER(RU_Raw!J14),RU_Raw!J14,IF(ISNUMBER(RU_Raw!J15),(J13+RU_Raw!J15)/2,IF(ISNUMBER(RU_Raw!J16),J13+(RU_Raw!J16-J13)/3,""))) -> 111.2 | K14: =IF(ISNUMBER(RU_Raw!K14),RU_Raw!K14,IF(ISNUMBER(RU_Raw!K15),(K13+RU_Raw!K15)/2,IF(ISNUMBER(RU_Raw!K16),K13+(RU_Raw!K16-K13)/3,""))) -> 105.7 | L14: =IF(ISNUMBER(RU_Raw!L14),RU_Raw!L14,IF(ISNUMBER(RU_Raw!L15),(L13+RU_Raw!L15)/2,IF(ISNUMBER(RU_Raw!L16),L13+(RU_Raw!L16-L13)/3,""))) -> 109.9 | M14: =IF(ISNUMBER(RU_Raw!M14),RU_Raw!M14,IF(ISNUMBER(RU_Raw!M15),(M13+RU_Raw!M15)/2,IF(ISNUMBER(RU_Raw!M16),M13+(RU_Raw!M16-M13)/3,""))) -> 171.2 | N14: =IF(ISNUMBER(RU_Raw!N14),RU_Raw!N14,IF(ISNUMBER(RU_Raw!N15),(N13+RU_Raw!N15)/2,IF(ISNUMBER(RU_Raw!N16),N13+(RU_Raw!N16-N13)/3,""))) -> 107.3 | ... AG14: =IF(ISNUMBER(RU_Raw!AG14),RU_Raw!AG14,IF(ISNUMBER(RU_Raw!AG15),(AG13+RU_Raw!AG15)/2,IF(ISNUMBER(RU_Raw!AG16),AG13+(RU_Raw!AG16-AG13)/3,""))) -> 114.8 | AH14: =SUM(G14:R14) -> 1390
A15: =RU_Raw!A15 -> 2013 | B15: =RU_Raw!B15 -> 11 | C15: =RU_Raw!C15 -> November | D15: =RU_Raw!D15 -> 41579 | E15: =COUNTBLANK(RU_Raw!G15:AG15) -> 0 | F15: =IF(E15>0,"Imputed","") | G15: =IF(ISNUMBER(RU_Raw!G15),RU_Raw!G15,IF(ISNUMBER(RU_Raw!G16),(G14+RU_Raw!G16)/2,IF(ISNUMBER(RU_Raw!G17),G14+(RU_Raw!G17-G14)/3,""))) -> 118.1 | H15: =IF(ISNUMBER(RU_Raw!H15),RU_Raw!H15,IF(ISNUMBER(RU_Raw!H16),(H14+RU_Raw!H16)/2,IF(ISNUMBER(RU_Raw!H17),H14+(RU_Raw!H17-H14)/3,""))) -> 115.4 | I15: =IF(ISNUMBER(RU_Raw!I15),RU_Raw!I15,IF(ISNUMBER(RU_Raw!I16),(I14+RU_Raw!I16)/2,IF(ISNUMBER(RU_Raw!I17),I14+(RU_Raw!I17-I14)/3,""))) -> 118.7 | J15: =IF(ISNUMBER(RU_Raw!J15),RU_Raw!J15,IF(ISNUMBER(RU_Raw!J16),(J14+RU_Raw!J16)/2,IF(ISNUMBER(RU_Raw!J17),J14+(RU_Raw!J17-J14)/3,""))) -> 112.5 | K15: =IF(ISNUMBER(RU_Raw!K15),RU_Raw!K15,IF(ISNUMBER(RU_Raw!K16),(K14+RU_Raw!K16)/2,IF(ISNUMBER(RU_Raw!K17),K14+(RU_Raw!K17-K14)/3,""))) -> 106.8 | L15: =IF(ISNUMBER(RU_Raw!L15),RU_Raw!L15,IF(ISNUMBER(RU_Raw!L16),(L14+RU_Raw!L16)/2,IF(ISNUMBER(RU_Raw!L17),L14+(RU_Raw!L17-L14)/3,""))) -> 113.5 | M15: =IF(ISNUMBER(RU_Raw!M15),RU_Raw!M15,IF(ISNUMBER(RU_Raw!M16),(M14+RU_Raw!M16)/2,IF(ISNUMBER(RU_Raw!M17),M14+(RU_Raw!M17-M14)/3,""))) -> 183.1 | N15: =IF(ISNUMBER(RU_Raw!N15),RU_Raw!N15,IF(ISNUMBER(RU_Raw!N16),(N14+RU_Raw!N16)/2,IF(ISNUMBER(RU_Raw!N17),N14+(RU_Raw!N17-N14)/3,""))) -> 108.2 | ... AG15: =IF(ISNUMBER(RU_Raw!AG15),RU_Raw!AG15,IF(ISNUMBER(RU_Raw!AG16),(AG14+RU_Raw!AG16)/2,IF(ISNUMBER(RU_Raw!AG17),AG14+(RU_Raw!AG17-AG14)/3,""))) -> 116.3 | AH15: =SUM(G15:R15) -> 1416.2
A16: =RU_Raw!A16 -> 2013 | B16: =RU_Raw!B16 -> 12 | C16: =RU_Raw!C16 -> December | D16: =RU_Raw!D16 -> 41609 | E16: =COUNTBLANK(RU_Raw!G16:AG16) -> 0 | F16: =IF(E16>0,"Imputed","") | G16: =IF(ISNUMBER(RU_Raw!G16),RU_Raw!G16,IF(ISNUMBER(RU_Raw!G17),(G15+RU_Raw!G17)/2,IF(ISNUMBER(RU_Raw!G18),G15+(RU_Raw!G18-G15)/3,""))) -> 119.1 | H16: =IF(ISNUMBER(RU_Raw!H16),RU_Raw!H16,IF(ISNUMBER(RU_Raw!H17),(H15+RU_Raw!H17)/2,IF(ISNUMBER(RU_Raw!H18),H15+(RU_Raw!H18-H15)/3,""))) -> 116.7 | I16: =IF(ISNUMBER(RU_Raw!I16),RU_Raw!I16,IF(ISNUMBER(RU_Raw!I17),(I15+RU_Raw!I17)/2,IF(ISNUMBER(RU_Raw!I18),I15+(RU_Raw!I18-I15)/3,""))) -> 123.5 | J16: =IF(ISNUMBER(RU_Raw!J16),RU_Raw!J16,IF(ISNUMBER(RU_Raw!J17),(J15+RU_Raw!J17)/2,IF(ISNUMBER(RU_Raw!J18),J15+(RU_Raw!J18-J15)/3,""))) -> 113.4 | K16: =IF(ISNUMBER(RU_Raw!K16),RU_Raw!K16,IF(ISNUMBER(RU_Raw!K17),(K15+RU_Raw!K17)/2,IF(ISNUMBER(RU_Raw!K18),K15+(RU_Raw!K18-K15)/3,""))) -> 107.3 | L16: =IF(ISNUMBER(RU_Raw!L16),RU_Raw!L16,IF(ISNUMBER(RU_Raw!L17),(L15+RU_Raw!L17)/2,IF(ISNUMBER(RU_Raw!L18),L15+(RU_Raw!L18-L15)/3,""))) -> 113.3 | M16: =IF(ISNUMBER(RU_Raw!M16),RU_Raw!M16,IF(ISNUMBER(RU_Raw!M17),(M15+RU_Raw!M17)/2,IF(ISNUMBER(RU_Raw!M18),M15+(RU_Raw!M18-M15)/3,""))) -> 145.4 | N16: =IF(ISNUMBER(RU_Raw!N16),RU_Raw!N16,IF(ISNUMBER(RU_Raw!N17),(N15+RU_Raw!N17)/2,IF(ISNUMBER(RU_Raw!N18),N15+(RU_Raw!N18-N15)/3,""))) -> 108.7 | ... AG16: =IF(ISNUMBER(RU_Raw!AG16),RU_Raw!AG16,IF(ISNUMBER(RU_Raw!AG17),(AG15+RU_Raw!AG17)/2,IF(ISNUMBER(RU_Raw!AG18),AG15+(RU_Raw!AG18-AG15)/3,""))) -> 114.5 | AH16: =SUM(G16:R16) -> 1388.9
... A129: =RU_Raw!A129 -> 2023 | B129: =RU_Raw!B129 -> 5 | C129: =RU_Raw!C129 -> May | D129: =RU_Raw!D129 -> 45047 | E129: =COUNTBLANK(RU_Raw!G129:AG129) -> 0 | F129: =IF(E129>0,"Imputed","") | G129: =IF(ISNUMBER(RU_Raw!G129),RU_Raw!G129,IF(ISNUMBER(RU_Raw!G130),(G128+RU_Raw!G130)/2,IF(ISNUMBER(RU_Raw!G131),G128+(RU_Raw!G131-G128)/3,""))) -> 173.7 | H129: =IF(ISNUMBER(RU_Raw!H129),RU_Raw!H129,IF(ISNUMBER(RU_Raw!H130),(H128+RU_Raw!H130)/2,IF(ISNUMBER(RU_Raw!H131),H128+(RU_Raw!H131-H128)/3,""))) -> 214.3 | I129: =IF(ISNUMBER(RU_Raw!I129),RU_Raw!I129,IF(ISNUMBER(RU_Raw!I130),(I128+RU_Raw!I130)/2,IF(ISNUMBER(RU_Raw!I131),I128+(RU_Raw!I131-I128)/3,""))) -> 173.2 | J129: =IF(ISNUMBER(RU_Raw!J129),RU_Raw!J129,IF(ISNUMBER(RU_Raw!J130),(J128+RU_Raw!J130)/2,IF(ISNUMBER(RU_Raw!J131),J128+(RU_Raw!J131-J128)/3,""))) -> 179.5 | K129: =IF(ISNUMBER(RU_Raw!K129),RU_Raw!K129,IF(ISNUMBER(RU_Raw!K130),(K128+RU_Raw!K130)/2,IF(ISNUMBER(RU_Raw!K131),K128+(RU_Raw!K131-K128)/3,""))) -> 170 | L129: =IF(ISNUMBER(RU_Raw!L129),RU_Raw!L129,IF(ISNUMBER(RU_Raw!L130),(L128+RU_Raw!L130)/2,IF(ISNUMBER(RU_Raw!L131),L128+(RU_Raw!L131-L128)/3,""))) -> 172.2 | M129: =IF(ISNUMBER(RU_Raw!M129),RU_Raw!M129,IF(ISNUMBER(RU_Raw!M130),(M128+RU_Raw!M130)/2,IF(ISNUMBER(RU_Raw!M131),M128+(RU_Raw!M131-M128)/3,""))) -> 161 | N129: =IF(ISNUMBER(RU_Raw!N129),RU_Raw!N129,IF(ISNUMBER(RU_Raw!N130),(N128+RU_Raw!N130)/2,IF(ISNUMBER(RU_Raw!N131),N128+(RU_Raw!N131-N128)/3,""))) -> 175.6 | ... AG129: =IF(ISNUMBER(RU_Raw!AG129),RU_Raw!AG129,IF(ISNUMBER(RU_Raw!AG130),(AG128+RU_Raw!AG130)/2,IF(ISNUMBER(RU_Raw!AG131),AG128+(RU_Raw!AG131-AG128)/3,""))) -> 179.1 | AH129: =SUM(G129:R129) -> 2127.8

Sheet MoM
A1: Month-on-month inflation % (Rural+Urban)
A2: Formula: (current - earlier) / earlier x 100, from RU_Clean
A4: Year | B4: MonthNo | C4: Month | D4: Date | G4: Cereals and products | H4: Meat and fish | I4: Egg | J4: Milk and products | K4: Oils and fats | L4: Fruits | M4: Vegetables | N4: Pulses and products | O4: Sugar and Confectionery | P4: Spices | Q4: Non-alcoholic beverages | R4: Prepared meals, snacks, sweets etc. | S4: Food and beverages | T4: Pan, tobacco and intoxicants | U4: Clothing | V4: Footwear | W4: Clothing and footwear | X4: Housing | Y4: Fuel and light | Z4: Household goods and services | AA4: Health | AB4: Transport and communication | AC4: Recreation and amusement | AD4: Education | AE4: Personal care and effects | AF4: Miscellaneous | AG4: General index | AH4: Food bucket (sum of 12 food items)
A5: =RU_Clean!A5 -> 2013 | B5: =RU_Clean!B5 -> 1 | C5: =RU_Clean!C5 -> January | D5: =RU_Clean!D5 -> 41275
A6: =RU_Clean!A6 -> 2013 | B6: =RU_Clean!B6 -> 2 | C6: =RU_Clean!C6 -> February | D6: =RU_Clean!D6 -> 41306 | G6: =IF(AND(ISNUMBER(RU_Clean!G6),ISNUMBER(RU_Clean!G5)),(RU_Clean!G6-RU_Clean!G5)/RU_Clean!G5*100,"") -> 1.8450185 | H6: =IF(AND(ISNUMBER(RU_Clean!H6),ISNUMBER(RU_Clean!H5)),(RU_Clean!H6-RU_Clean!H5)/RU_Clean!H5*100,"") -> 2.7027027 | I6: =IF(AND(ISNUMBER(RU_Clean!I6),ISNUMBER(RU_Clean!I5)),(RU_Clean!I6-RU_Clean!I5)/RU_Clean!I5*100,"") -> 2.5454545 | J6: =IF(AND(ISNUMBER(RU_Clean!J6),ISNUMBER(RU_Clean!J5)),(RU_Clean!J6-RU_Clean!J5)/RU_Clean!J5*100,"") -> 0.4789272 | K6: =IF(AND(ISNUMBER(RU_Clean!K6),ISNUMBER(RU_Clean!K5)),(RU_Clean!K6-RU_Clean!K5)/RU_Clean!K5*100,"") -> 0.38058991 | L6: =IF(AND(ISNUMBER(RU_Clean!L6),ISNUMBER(RU_Clean!L5)),(RU_Clean!L6-RU_Clean!L5)/RU_Clean!L5*100,"") -> 0.3875969 | M6: =IF(AND(ISNUMBER(RU_Clean!M6),ISNUMBER(RU_Clean!M5)),(RU_Clean!M6-RU_Clean!M5)/RU_Clean!M5*100,"") -> 0.97847358 | N6: =IF(AND(ISNUMBER(RU_Clean!N6),ISNUMBER(RU_Clean!N5)),(RU_Clean!N6-RU_Clean!N5)/RU_Clean!N5*100,"") -> -0.66037736 | ... AH6: =IF(AND(ISNUMBER(RU_Clean!AH6),ISNUMBER(RU_Clean!AH5)),(RU_Clean!AH6-RU_Clean!AH5)/RU_Clean!AH5*100,"") -> 0.78094186
A7: =RU_Clean!A7 -> 2013 | B7: =RU_Clean!B7 -> 3 | C7: =RU_Clean!C7 -> March | D7: =RU_Clean!D7 -> 41334 | G7: =IF(AND(ISNUMBER(RU_Clean!G7),ISNUMBER(RU_Clean!G6)),(RU_Clean!G7-RU_Clean!G6)/RU_Clean!G6*100,"") -> 0.9057971 | H7: =IF(AND(ISNUMBER(RU_Clean!H7),ISNUMBER(RU_Clean!H6)),(RU_Clean!H7-RU_Clean!H6)/RU_Clean!H6*100,"") -> -0.45372051 | I7: =IF(AND(ISNUMBER(RU_Clean!I7),ISNUMBER(RU_Clean!I6)),(RU_Clean!I7-RU_Clean!I6)/RU_Clean!I6*100,"") -> -1.4184397 | J7: =IF(AND(ISNUMBER(RU_Clean!J7),ISNUMBER(RU_Clean!J6)),(RU_Clean!J7-RU_Clean!J6)/RU_Clean!J6*100,"") -> 0.19065777 | K7: =IF(AND(ISNUMBER(RU_Clean!K7),ISNUMBER(RU_Clean!K6)),(RU_Clean!K7-RU_Clean!K6)/RU_Clean!K6*100,"") -> -0.56872038 | L7: =IF(AND(ISNUMBER(RU_Clean!L7),ISNUMBER(RU_Clean!L6)),(RU_Clean!L7-RU_Clean!L6)/RU_Clean!L6*100,"") -> 1.6409266 | M7: =IF(AND(ISNUMBER(RU_Clean!M7),ISNUMBER(RU_Clean!M6)),(RU_Clean!M7-RU_Clean!M6)/RU_Clean!M6*100,"") -> -0.96899225 | N7: =IF(AND(ISNUMBER(RU_Clean!N7),ISNUMBER(RU_Clean!N6)),(RU_Clean!N7-RU_Clean!N6)/RU_Clean!N6*100,"") -> -0.28490028 | ... AH7: =IF(AND(ISNUMBER(RU_Clean!AH7),ISNUMBER(RU_Clean!AH6)),(RU_Clean!AH7-RU_Clean!AH6)/RU_Clean!AH6*100,"") -> -0.03913588
A8: =RU_Clean!A8 -> 2013 | B8: =RU_Clean!B8 -> 4 | C8: =RU_Clean!C8 -> April | D8: =RU_Clean!D8 -> 41365 | G8: =IF(AND(ISNUMBER(RU_Clean!G8),ISNUMBER(RU_Clean!G7)),(RU_Clean!G8-RU_Clean!G7)/RU_Clean!G7*100,"") -> 0.17953321 | H8: =IF(AND(ISNUMBER(RU_Clean!H8),ISNUMBER(RU_Clean!H7)),(RU_Clean!H8-RU_Clean!H7)/RU_Clean!H7*100,"") -> 1.0938924 | I8: =IF(AND(ISNUMBER(RU_Clean!I8),ISNUMBER(RU_Clean!I7)),(RU_Clean!I8-RU_Clean!I7)/RU_Clean!I7*100,"") -> -4.1366906 | J8: =IF(AND(ISNUMBER(RU_Clean!J8),ISNUMBER(RU_Clean!J7)),(RU_Clean!J8-RU_Clean!J7)/RU_Clean!J7*100,"") -> 0.57088487 | K8: =IF(AND(ISNUMBER(RU_Clean!K8),ISNUMBER(RU_Clean!K7)),(RU_Clean!K8-RU_Clean!K7)/RU_Clean!K7*100,"") -> -0.47664442 | L8: =IF(AND(ISNUMBER(RU_Clean!L8),ISNUMBER(RU_Clean!L7)),(RU_Clean!L8-RU_Clean!L7)/RU_Clean!L7*100,"") -> 3.4188034 | M8: =IF(AND(ISNUMBER(RU_Clean!M8),ISNUMBER(RU_Clean!M7)),(RU_Clean!M8-RU_Clean!M7)/RU_Clean!M7*100,"") -> 3.2289628 | N8: =IF(AND(ISNUMBER(RU_Clean!N8),ISNUMBER(RU_Clean!N7)),(RU_Clean!N8-RU_Clean!N7)/RU_Clean!N7*100,"") -> 0.28571429 | ... AH8: =IF(AND(ISNUMBER(RU_Clean!AH8),ISNUMBER(RU_Clean!AH7)),(RU_Clean!AH8-RU_Clean!AH7)/RU_Clean!AH7*100,"") -> 0.42283298
